Workbook
Name Base_ProForma_EPS: Accretion_Dilution!$E$9
Name Base_SA_EPS: Accretion_Dilution!$E$8
Name Base_Synergy: Assumptions!$C$52
Name Exit_EBITDA_Multiple: Assumptions!$C$78
Name Phase_Y3: Assumptions!$C$55
Name Tax_Rate: Assumptions!$C$12
Name Total_Shares: Assumptions!$C$92
Name Y5_Acq_Debt: Pro_Forma_BS!$H$18
Name Y5_Cash: Pro_Forma_BS!$H$8
Name Y5_EBITDA: Pro_Forma_IS!$G$29
Name Y5_New_Debt: Pro_Forma_BS!$H$19

Sheet Cover
B2: M&A Accretion / Dilution Model
B3: Transaction Analysis (v3 — institutional rebuild)
B5: Sheet Index
B6: =HYPERLINK("#'Assumptions'!A1","Assumptions") -> Assumptions | C6: Inputs — acquirer, target, deal terms, synergies, PPA
B7: =HYPERLINK("#'Transaction_Summary'!A1","Transaction_Summary") -> Transaction_Summary | C7: Sources & Uses, PPA bridge, implied multiples, exchange ratio
B8: =HYPERLINK("#'Pro_Forma_IS'!A1","Pro_Forma_IS") -> Pro_Forma_IS | C8: Combined income statement with synergies + deal-fee amort + integration
B9: =HYPERLINK("#'Pro_Forma_BS'!A1","Pro_Forma_BS") -> Pro_Forma_BS | C9: Day 1 + 5-year pro-forma balance sheet with check
B10: =HYPERLINK("#'Pro_Forma_CF'!A1","Pro_Forma_CF") -> Pro_Forma_CF | C10: 5-year cash flow statement tying to BS
B11: =HYPERLINK("#'Standalone_IS'!A1","Standalone_IS") -> Standalone_IS | C11: Acquirer-only P&L (counterfactual)
B12: =HYPERLINK("#'Accretion_Dilution'!A1","Accretion_Dilution") -> Accretion_Dilution | C12: EPS comparison, $ contribution bridge, $/share EPS bridge
B13: =HYPERLINK("#'Credit_Metrics'!A1","Credit_Metrics") -> Credit_Metrics | C13: Debt schedule + leverage and coverage ratios
B14: =HYPERLINK("#'Buyer_Returns'!A1","Buyer_Returns") -> Buyer_Returns | C14: Acquirer equity IRR + break-even cost synergies
B15: =HYPERLINK("#'Sensitivity'!A1","Sensitivity") -> Sensitivity | C15: Two-way grids: premium vs synergies; premium vs cash mix
B16: =HYPERLINK("#'Checks'!A1","Checks") -> Checks | C16: Consolidated integrity checks (PASS/FAIL)
B17: =HYPERLINK("#'Disclaimer'!A1","Disclaimer") -> Disclaimer | C17: Legal disclaimer, copyright, MIT license
B20: About this model
B21: Institutional-grade M&A model. Builds a pro-forma 3-statement combination (IS, BS, CF) of acquirer + target over 5 years with deal-fee amortisation, integration costs, tangible step-up, and a single-source-of-truth debt schedule. Outputs: accretion / dilution per year, EPS bridge (in $ and $/share), Sources & Uses, simplified PPA with goodwill, leverage and coverage metrics, buyer equity IRR with break-even cost synergies, and two-way sensitivity grids. Acknowledged simplifications: working capital flat (ΔWC = 0), no tax-shield modelling, no monthly cash, no FX. See design.md for the full simplification log.
B24: About this model
B25: An M&A Modeling & Valuation template provides comprehensive target valuation using three methods: standalone DCF (discounted cash flow with free cash flow projections), trading comparables (public company EV/EBITDA multiples), and precedent transactions (prior M&A deal multiples). The model builds a forward 5-year P&L for the target, computes unlevered free cash flow, applies a WACC (typically 7-10% for mid-market industrial targets), and derives enterprise value. Comparable company analysis extracts median EV/EBITDA, EV/Revenue, and P/E multiples from peer groups; precedent transactions adjust for deal timing and buyer-specific synergies. The final valuation range (football field) anchors buyer offer strategy and integration planning. Once valuation is established, the Deal_Structure sheet models pro-forma financing: all-cash, stock, or mixed consideration. The Synergies_Analysis quantifies cost synergies (headcount reduction, procurement savings, overhead elimination), revenue synergies (cross-sell, geographic expansion), and integration costs (severance, system migration). Pro-forma accretion/dilution is computed: if the buyer's existing EPS and the deal's pro-forma EPS diverge, the transaction is accretive (boosts EPS) or dilutive (reduces EPS) on a per-share basis. The Buyer_Returns sheet models levered cash returns to the buyerâequity IRR and cash-on-cash multipleâfactoring in deal leverage, exit multiple (typically flat to 50-100 bps compression), and hold period. Acquisition price sensitivities are crucial: buyer's walks if cost of capital or synergies don't support deal returns. This model is essential for M&A bankers, corporate development teams, and private equity sponsors evaluating acquisitions. Typical target valuation ranges from 6-12Ã EBITDA depending on industry and growth profile; buyer decision thresholds often require >15% levered IRR or >2.0Ã equity multiple. The three-method approach provides defensible negotiation fodder for both buyer and seller.
B27: About Finamodel
B28: A free, open library of institutional-quality financial models covering every industry — banking, real estate, energy, SaaS, biotech, infrastructure, and dozens more. Every cell is editable, every formula is transparent, and every template is built to be forked, adapted, and rebuilt for your own use case. MIT-licensed — use them commercially, share them, modify them, no attribution required.
B29: Thanks for downloading my templates! Feel free to check out other free templates on my site.
B30: — Alex Tapio, Founder of Finamodel.com

Sheet Dashboard
B2: Dashboard
B3: M&A accretion / dilution at a glance — deal, financing, synergies, pro-forma EPS
B5: Key Deal Metrics
B6: Equity Purchase Price | D6: Enterprise Value | F6: Offer Premium | H6: Run-rate Synergies | J6: New Acquisition Debt
B7: =Assumptions!C87 -> 2250 | D7: =Assumptions!C88 -> 2250 | F7: =Assumptions!C34 -> 0.25 | H7: =Assumptions!C50+Assumptions!C52 -> 350 | J7: =Assumptions!C91 -> -35
B9: Offer to target equity ($M | D9: Incl. assumed net debt ($M | F9: Over unaffected price | H9: Revenue + cost ($M/yr | J9: Debt financing ($M
B10: Pro-Forma EPS (Yr 1 | D10: Standalone EPS (Yr 1 | F10: Accretion / (Dilution) Yr1 | H10: Accretion / (Dilution) Yr5 | J10: PF Leverage (Yr 1)
B11: =Pro_Forma_IS!C50 -> 22.198356 | D11: =Standalone_IS!C21 -> 22.597727 | F11: =Accretion_Dilution!C12 -> -0.017673084 | H11: =Accretion_Dilution!G12 -> 0.012773515 | J11: =Credit_Metrics!C27 -> 0.38974999
B13: Combined entity | D13: Acquirer alone | F13: EPS vs standalone | H13: EPS vs standalone | J13: Debt / EBITDA
B15: Accretion / Dilution Summary by Year
B16: Metric | C16: =Accretion_Dilution!C6 -> Year 1 | D16: =Accretion_Dilution!D6 -> Year 2 | E16: =Accretion_Dilution!E6 -> Year 3 | F16: =Accretion_Dilution!F6 -> Year 4 | G16: =Accretion_Dilution!G6 -> Year 5
B17: Standalone EPS | C17: =Standalone_IS!C21 -> 22.597727 | D17: =Standalone_IS!D21 -> 23.773068 | E17: =Standalone_IS!E21 -> 25.004903 | F17: =Standalone_IS!F21 -> 26.296171 | G17: =Standalone_IS!G21 -> 27.649951
B18: Pro Forma EPS | C18: =Pro_Forma_IS!C50 -> 22.198356 | D18: =Pro_Forma_IS!D50 -> 23.67807 | E18: =Pro_Forma_IS!E50 -> 25.241309 | F18: =Pro_Forma_IS!F50 -> 26.644303 | G18: =Pro_Forma_IS!G50 -> 28.003139
B19: Accretion / (Dilution) % | C19: =Accretion_Dilution!C12 -> -0.017673084 | D19: =Accretion_Dilution!D12 -> -0.0039960399 | E19: =Accretion_Dilution!E12 -> 0.009454373 | F19: =Accretion_Dilution!F12 -> 0.013238862 | G19: =Accretion_Dilution!G12 -> 0.012773515
B20: Pro Forma Net Income | C20: =Pro_Forma_IS!C48 -> 7369.8541 | D20: =Pro_Forma_IS!D48 -> 7861.1193 | E20: =Pro_Forma_IS!E48 -> 8380.1146 | F20: =Pro_Forma_IS!F48 -> 8845.9085 | G20: =Pro_Forma_IS!G48 -> 9297.042
B21: Debt / EBITDA | C21: =Credit_Metrics!C27 -> 0.38974999 | D21: =Credit_Metrics!D27 -> 0.35161114 | E21: =Credit_Metrics!E27 -> 0.31734151 | F21: =Credit_Metrics!F27 -> 0.28652949 | G21: =Credit_Metrics!G27 -> 0.25963233
B23: Charts
B60: EPS Accretion / (Dilution) Bridge — Year 1 ($/share
B80: Consideration Mix (helper
B81: Cash Consideration | C81: =Assumptions!C87*Assumptions!C35 -> 1350
B82: Stock Consideration | C82: =Assumptions!C89 -> 900
B84: EPS Bridge Data (helper
B86: Standalone EPS | C86: =0 -> 0 | D86: =Standalone_IS!C21 -> 22.597727
B87: + Target Earnings | C87: =Standalone_IS!C21 -> 22.597727 | D87: =Accretion_Dilution!C33 -> 0.13540663
B88: + Synergies | C88: =Standalone_IS!C21+Accretion_Dilution!C33 -> 22.733134 | D88: =(Accretion_Dilution!C34+Accretion_Dilution!C35) -> 0.10730422
B89: Integration | C89: =Standalone_IS!C21+Accretion_Dilution!C33+(Accretion_Dilution!C34+Accretion_Dilution!C35)+Accretion_Dilution!C36 -> 22.67101 | D89: =-Accretion_Dilution!C36 -> 0.16942771
B90: Financing Cost | C90: =Standalone_IS!C21+Accretion_Dilution!C33+(Accretion_Dilution!C34+Accretion_Dilution!C35)+Accretion_Dilution!C36+(Accretion_Dilution!C39+Accretion_Dilution!C40) -> 22.573702 | D90: =-(Accretion_Dilution!C39+Accretion_Dilution!C40) -> 0.097307982
B91: PPA / Step-Up Amort | C91: =Standalone_IS!C21+Accretion_Dilution!C33+(Accretion_Dilution!C34+Accretion_Dilution!C35)+Accretion_Dilution!C36+(Accretion_Dilution!C39+Accretion_Dilution!C40)+(Accretion_Dilution!C37+Accretion_Dilution!C38) -> 22.49746 | D91: =-(Accretion_Dilution!C37+Accretion_Dilution!C38) -> 0.07624247
B92: Deal Fees | C92: =Standalone_IS!C21+Accretion_Dilution!C33+(Accretion_Dilution!C34+Accretion_Dilution!C35)+Accretion_Dilution!C36+(Accretion_Dilution!C39+Accretion_Dilution!C40)+(Accretion_Dilution!C37+Accretion_Dilution!C38)+(Accretion_Dilution!C41+Accretion_Dilution!C42) -> 22.334487 | D92: =-(Accretion_Dilution!C41+Accretion_Dilution!C42) -> 0.16297332
B93: Share Dilution Drag | C93: =Pro_Forma_IS!C50 -> 22.198356 | D93: =-Accretion_Dilution!C43 -> 0.13613089
B94: Pro Forma EPS | C94: =0 -> 0 | D94: =Pro_Forma_IS!C50 -> 22.198356

Sheet Assumptions
B2: Assumptions
B3: Key Inputs
B5: Acquirer Profile
B6: Revenue | C6: 46000 | D6: $M | E6: LTM revenue
B7: Revenue Growth | C7: 0.05 | D7: %
B8: EBITDA Margin | C8: 0.25 | D8: %
B9: D&A (% Revenue) | C9: 0.04 | D9: %
B10: Interest Expense | C10: 200 | D10: $M | E10: On existing debt (Y1 only
B11: Existing Debt Amort | C11: 0.05 | D11: % | E11: Annual principal paydown
B12: Tax Rate | C12: 0.25 | D12: %
B13: Share Price | C13: 450 | D13: $
B14: Shares Outstanding | C14: 330 | D14: M
B15: Existing Debt | C15: 5000 | D15: $M | E15: Pre-deal
B16: Cash | C16: 1500 | D16: $M | E16: Pre-deal BS
B17: Other Assets | C17: 8500 | D17: $M | E17: PP&E + intangibles pre-deal; tuned with Equity for BS balance
B18: Goodwill (pre-deal) | C18: 0 | D18: $M | E18: Existing book goodwill
B19: Other Liabilities | C19: 2000 | D19: $M | E19: Pre-deal
B20: Book Equity (pre-deal) | C20: 3000 | D20: $M | E20: Plug: Cash+Other+GW − Debt − OtherLiab; tuned for Day-1 BS balance
B22: Target Profile
B23: Revenue | C23: 150 | D23: $M | E23: LTM revenue
B24: Revenue Growth | C24: 0.08 | D24: %
B25: EBITDA Margin | C25: 0.4 | D25: %
B26: D&A (% Revenue | C26: 0.03 | D26: %
B27: Interest Expense | C27: 45 | D27: $M | E27: Standalone target interest — refinanced at close (assumption
B28: Tax Rate | C28: 0.25 | D28: %
B29: Share Price | C29: 18 | D29: $ | E29: Pre-announcement
B30: Shares Outstanding | C30: 100 | D30: M
B31: Net Debt | C31: 0 | D31: $M | E31: Refinanced via new debt at close
B33: Transaction Terms
B34: Offer Premium | C34: =Sensitivity!J9 -> 0.25 | D34: %
B35: Cash Percentage | C35: =Sensitivity!J10 -> 0.6 | D35: % | E35: % of equity consideration paid in cash
B36: Advisory Fees | C36: 65 | D36: $M | E36: Banker + legal + accounting
B37: Financing Fees | C37: 50 | D37: $M | E37: Underwriting OID — amortised over Debt_Tenor
B38: Acquirer Cash Used | C38: 1500 | D38: $M | E38: From acquirer BS
B39: Capitalise Advisory? | C39: =FALSE() -> FALSE | D39: TRUE/FALSE | E39: FALSE = expense Y1; TRUE = amortise over Deal_Asset_Life
B40: Deal Asset Life | C40: 10 | D40: years | E40: Amortisation period when Capitalise_Advisory = TRUE
B42: Financing
B43: New Debt Rate | C43: 0.055 | D43: %
B44: Debt Tenor | C44: 7 | D44: years | E44: Balloon maturity
B45: Amortisation | C45: 0.1 | D45: % | E45: Annual % of original principal
...

Sheet Transaction_Summary
B2: Transaction Summary
B3: Deal Structure & PPA
B6: Sources | C6: $M | E6: Uses | F6: $M
B7: New Debt | C7: =Assumptions!C91 -> -35 | E7: Equity Purchase | F7: =Assumptions!C87 -> 2250
B8: Stock Consideration | C8: =Assumptions!C89 -> 900 | E8: Target Net Debt | F8: =Assumptions!C31 -> 0
B9: Cash from BS | C9: =Assumptions!C38 -> 1500 | E9: Advisory Fees | F9: =Assumptions!C36 -> 65
E10: Financing Fees | F10: =Assumptions!C37 -> 50
B11: TOTAL SOURCES | C11: =SUM(C7:C9) -> 2365 | E11: TOTAL USES | F11: =SUM(F7:F10) -> 2365
B13: Sources − Uses | C13: =C11-F11 -> 0 | E13: Must = 0
B15: Purchase Price Allocation | C15: $M
B16: Enterprise Value | C16: =Assumptions!C88 -> 2250
B17: Net Tangible Assets (gross) | C17: =Assumptions!C23*Assumptions!C68 -> 45 | E17: Tgt_Revenue × NTA_Pct (no net-debt deduction
B18: Tangible Step-Up (diagnostic) | C18: =C17*Assumptions!C69/Assumptions!C70*Assumptions!C70 -> 2.25 | E18: Fair-value mark on tangibles — subsumed in GW (v3
B19: Intangible Assets | C19: =Assumptions!C88*Assumptions!C71 -> 337.5
B20: Target Net Debt (assumed) | C20: =Assumptions!C31 -> 0 | E20: Refinanced by new debt at close
B21: Deferred Tax Liability | C21: =C19*Assumptions!C73 -> 84.375 | E21: Tax on intangible step-up (DTL on tangible step-up tracked separately on BS
B22: GOODWILL | C22: =C16-C17-C19+C21 -> 1951.875 | E22: EV − NTA(gross) − Intangibles + DTL
B24: PPA Check | C24: =Assumptions!C87-C17-C19-C22+C21+C20 -> 0 | E24: Independent check via Equity_Purchase = NTA + Intang + GW − DTL − Net Debt
B26: Implied Multiples
B27: EV / Revenue | C27: =Assumptions!C88/Assumptions!C23 -> 15
B28: EV / EBITDA | C28: =Assumptions!C88/(Assumptions!C23*Assumptions!C25) -> 37.5
B29: Price / Earnings | C29: =Assumptions!C87/((Assumptions!C23*Assumptions!C25-Assumptions!C23*Assumptions!C26-Assumptions!C27)*(1-Assumptions!C28)) -> 285.71429
B30: Offer Premium | C30: =Assumptions!C34 -> 0.25
B31: Exchange Ratio | C31: =Assumptions!C89/Assumptions!C13/Assumptions!C30 -> 0.02 | E31: Acquirer shares per target share

Sheet Pro_Forma_IS
B2: Pro Forma Income Statement
B3: Combined Entity — 5-year projection
B6: $M | C6: Year 1 | D6: Year 2 | E6: Year 3 | F6: Year 4 | G6: Year 5
B7: Acquirer
B8: Revenue | C8: =Assumptions!C6*(1+Assumptions!C7)^1 -> 48300 | D8: =Assumptions!C6*(1+Assumptions!C7)^2 -> 50715 | E8: =Assumptions!C6*(1+Assumptions!C7)^3 -> 53250.75 | F8: =Assumptions!C6*(1+Assumptions!C7)^4 -> 55913.287 | G8: =Assumptions!C6*(1+Assumptions!C7)^5 -> 58708.952
B9: EBITDA | C9: =C8*Assumptions!C8 -> 12075 | D9: =D8*Assumptions!C8 -> 12678.75 | E9: =E8*Assumptions!C8 -> 13312.688 | F9: =F8*Assumptions!C8 -> 13978.322 | G9: =G8*Assumptions!C8 -> 14677.238
B10: D&A | C10: =C8*Assumptions!C9 -> 1932 | D10: =D8*Assumptions!C9 -> 2028.6 | E10: =E8*Assumptions!C9 -> 2130.03 | F10: =F8*Assumptions!C9 -> 2236.5315 | G10: =G8*Assumptions!C9 -> 2348.3581
B11: Acquirer EBIT | C11: =C9-C10 -> 10143 | D11: =D9-D10 -> 10650.15 | E11: =E9-E10 -> 11182.658 | F11: =F9-F10 -> 11741.79 | G11: =G9-G10 -> 12328.88
B13: Target
B14: Revenue | C14: =Assumptions!C23*(1+Assumptions!C24)^1 -> 162 | D14: =Assumptions!C23*(1+Assumptions!C24)^2 -> 174.96 | E14: =Assumptions!C23*(1+Assumptions!C24)^3 -> 188.9568 | F14: =Assumptions!C23*(1+Assumptions!C24)^4 -> 204.07334 | G14: =Assumptions!C23*(1+Assumptions!C24)^5 -> 220.39921
B15: EBITDA | C15: =C14*Assumptions!C25 -> 64.8 | D15: =D14*Assumptions!C25 -> 69.984 | E15: =E14*Assumptions!C25 -> 75.58272 | F15: =F14*Assumptions!C25 -> 81.629338 | G15: =G14*Assumptions!C25 -> 88.159685
B16: D&A | C16: =C14*Assumptions!C26 -> 4.86 | D16: =D14*Assumptions!C26 -> 5.2488 | E16: =E14*Assumptions!C26 -> 5.668704 | F16: =F14*Assumptions!C26 -> 6.1222003 | G16: =G14*Assumptions!C26 -> 6.6119763
B17: Target EBIT | C17: =C15-C16 -> 59.94 | D17: =D15-D16 -> 64.7352 | E17: =E15-E16 -> 69.914016 | F17: =F15-F16 -> 75.507137 | G17: =G15-G16 -> 81.547708
B19: Synergies
B20: Revenue Synergies | C20: =Assumptions!C50*Assumptions!C53 -> 50 | D20: =Assumptions!C50*Assumptions!C54 -> 100 | E20: =Assumptions!C50*Assumptions!C55 -> 150 | F20: =Assumptions!C50*Assumptions!C56 -> 200 | G20: =Assumptions!C50*Assumptions!C57 -> 200
B21: Synergy EBITDA | C21: =C20*Assumptions!C51 -> 10 | D21: =D20*Assumptions!C51 -> 20 | E21: =E20*Assumptions!C51 -> 30 | F21: =F20*Assumptions!C51 -> 40 | G21: =G20*Assumptions!C51 -> 40
B22: Cost Synergies | C22: =Assumptions!C52*Assumptions!C53 -> 37.5 | D22: =Assumptions!C52*Assumptions!C54 -> 75 | E22: =Assumptions!C52*Assumptions!C55 -> 112.5 | F22: =Assumptions!C52*Assumptions!C56 -> 150 | G22: =Assumptions!C52*Assumptions!C57 -> 150
B23: Total Synergy EBITDA | C23: =C21+C22 -> 47.5 | D23: =D21+D22 -> 95 | E23: =E21+E22 -> 142.5 | F23: =F21+F22 -> 190 | G23: =G21+G22 -> 190
B25: Combined
B26: Combined Revenue | C26: =C8+C14+C20 -> 48512 | D26: =D8+D14+D20 -> 50989.96 | E26: =E8+E14+E20 -> 53589.707 | F26: =F8+F14+F20 -> 56317.361 | G26: =G8+G14+G20 -> 59129.351
B27: Combined EBITDA (gross | C27: =C9+C15+C23 -> 12187.3 | D27: =D9+D15+D23 -> 12843.734 | E27: =E9+E15+E23 -> 13530.77 | F27: =F9+F15+F23 -> 14249.951 | G27: =G9+G15+G23 -> 14955.398
B28: Integration Costs | C28: =-Assumptions!C52*Assumptions!C60*Assumptions!C61 -> -75 | D28: =-Assumptions!C52*Assumptions!C60*Assumptions!C62 -> -75 | E28: =-Assumptions!C52*Assumptions!C60*Assumptions!C63 -> 0 | F28: =-Assumptions!C52*Assumptions!C60*Assumptions!C64 -> 0 | G28: =-Assumptions!C52*Assumptions!C60*Assumptions!C65 -> 0
B29: Combined EBITDA (net of integration | C29: =C27+C28 -> 12112.3 | D29: =D27+D28 -> 12768.734 | E29: =E27+E28 -> 13530.77 | F29: =F27+F28 -> 14249.951 | G29: =G27+G28 -> 14955.398
B30: Combined D&A | C30: =C10+C16 -> 1936.86 | D30: =D10+D16 -> 2033.8488 | E30: =E10+E16 -> 2135.6987 | F30: =F10+F16 -> 2242.6537 | G30: =G10+G16 -> 2354.9701
B31: PPA Intangible Amort | C31: =Transaction_Summary!C19/Assumptions!C72 -> 33.75 | D31: =Transaction_Summary!C19/Assumptions!C72 -> 33.75 | E31: =Transaction_Summary!C19/Assumptions!C72 -> 33.75 | F31: =Transaction_Summary!C19/Assumptions!C72 -> 33.75 | G31: =Transaction_Summary!C19/Assumptions!C72 -> 33.75
B32: Tangible Step-Up Amort (subsumed | C32: =0 -> 0 | D32: =0 -> 0 | E32: =0 -> 0 | F32: =0 -> 0 | G32: =0 -> 0
B33: Total D&A | C33: =C30+C31+C32 -> 1970.61 | D33: =D30+D31+D32 -> 2067.5988 | E33: =E30+E31+E32 -> 2169.4487 | F33: =F30+F31+F32 -> 2276.4037 | G33: =G30+G31+G32 -> 2388.7201
B34: Combined EBIT | C34: =C29-C33 -> 10141.69 | D34: =D29-D33 -> 10701.135 | E34: =E29-E33 -> 11361.322 | F34: =F29-F33 -> 11973.548 | G34: =G29-G33 -> 12566.678
B36: Interest & Deal-Related Expense
B37: Acquirer Interest | C37: =C18*0+Credit_Metrics!C18 -> 200 | D37: =D18*0+Credit_Metrics!D18 -> 190 | E37: =E18*0+Credit_Metrics!E18 -> 180.5 | F37: =F18*0+Credit_Metrics!F18 -> 171.475 | G37: =G18*0+Credit_Metrics!G18 -> 162.90125
B38: New Debt Interest | C38: =Credit_Metrics!C12 -> -1.925 | D38: =Credit_Metrics!D12 -> 0 | E38: =Credit_Metrics!E12 -> 0.1925 | F38: =Credit_Metrics!F12 -> 0.385 | G38: =Credit_Metrics!G12 -> 0.5775
B39: Total Debt Interest | C39: =C37+C38 -> 198.075 | D39: =D37+D38 -> 190 | E39: =E37+E38 -> 180.6925 | F39: =F37+F38 -> 171.86 | G39: =G37+G38 -> 163.47875
B40: Transaction Fees | C40: =IF(Assumptions!C39,Assumptions!C36/Assumptions!C40,Assumptions!C36) -> 65 | D40: =IF(Assumptions!C39,IF(2<=Assumptions!C40,Assumptions!C36/Assumptions!C40,0),0) -> 0 | E40: =IF(Assumptions!C39,IF(3<=Assumptions!C40,Assumptions!C36/Assumptions!C40,0),0) -> 0 | F40: =IF(Assumptions!C39,IF(4<=Assumptions!C40,Assumptions!C36/Assumptions!C40,0),0) -> 0 | G40: =IF(Assumptions!C39,IF(5<=Assumptions!C40,Assumptions!C36/Assumptions!C40,0),0) -> 0
B41: Financing Fee Amortisation | C41: =IF(1<=Assumptions!C44,Assumptions!C37/Assumptions!C44,0) -> 7.1428571 | D41: =IF(2<=Assumptions!C44,Assumptions!C37/Assumptions!C44,0) -> 7.1428571 | E41: =IF(3<=Assumptions!C44,Assumptions!C37/Assumptions!C44,0) -> 7.1428571 | F41: =IF(4<=Assumptions!C44,Assumptions!C37/Assumptions!C44,0) -> 7.1428571 | G41: =IF(5<=Assumptions!C44,Assumptions!C37/Assumptions!C44,0) -> 7.1428571
B42: Foregone Cash Interest | C42: =MAX(0,Assumptions!C38*Assumptions!C46*MAX(0,1-(0)/Assumptions!C47)) -> 45 | D42: =MAX(0,Assumptions!C38*Assumptions!C46*MAX(0,1-(1)/Assumptions!C47)) -> 22.5 | E42: =MAX(0,Assumptions!C38*Assumptions!C46*MAX(0,1-(2)/Assumptions!C47)) -> 0 | F42: =MAX(0,Assumptions!C38*Assumptions!C46*MAX(0,1-(3)/Assumptions!C47)) -> 0 | G42: =MAX(0,Assumptions!C38*Assumptions!C46*MAX(0,1-(4)/Assumptions!C47)) -> 0
B43: Total Other Deal Expense | C43: =C40+C41+C42 -> 117.14286 | D43: =D40+D41+D42 -> 29.642857 | E43: =E40+E41+E42 -> 7.1428571 | F43: =F40+F41+F42 -> 7.1428571 | G43: =G40+G41+G42 -> 7.1428571
B45: Pro Forma EBT | C45: =C34-C39-C43 -> 9826.4721 | D45: =D34-D39-D43 -> 10481.492 | E45: =E34-E39-E43 -> 11173.486 | F45: =F34-F39-F43 -> 11794.545 | G45: =G34-G39-G43 -> 12396.056
B46: Tax | C46: =C45*Assumptions!C12 -> 2456.618 | D46: =D45*Assumptions!C12 -> 2620.3731 | E46: =E45*Assumptions!C12 -> 2793.3715 | F46: =F45*Assumptions!C12 -> 2948.6362 | G46: =G45*Assumptions!C12 -> 3099.014
B48: PRO FORMA NET INCOME | C48: =C45-C46 -> 7369.8541 | D48: =D45-D46 -> 7861.1193 | E48: =E45-E46 -> 8380.1146 | F48: =F45-F46 -> 8845.9085 | G48: =G45-G46 -> 9297.042
B50: Pro Forma EPS | C50: =C48/Assumptions!C92 -> 22.198356 | D50: =D48/Assumptions!C92 -> 23.67807 | E50: =E48/Assumptions!C92 -> 25.241309 | F50: =F48/Assumptions!C92 -> 26.644303 | G50: =G48/Assumptions!C92 -> 28.003139

Sheet Pro_Forma_BS
B2: Pro Forma Balance Sheet
B3: Day 1 + 5-year projection
B6: $M | C6: Day 1 | D6: Year 1 | E6: Year 2 | F6: Year 3 | G6: Year 4 | H6: Year 5
B7: Assets
B8: Cash | C8: =Assumptions!C16-Assumptions!C38 -> 0 | D8: =Pro_Forma_CF!C32 -> 6268.2761 | E8: =Pro_Forma_CF!D32 -> 12868.214 | F8: =Pro_Forma_CF!E32 -> 19919.081 | G8: =Pro_Forma_CF!F32 -> 27378.99 | H8: =Pro_Forma_CF!G32 -> 35238.48
B9: Other Assets (PP&E, etc. | C9: =Assumptions!C17+Assumptions!C23*Assumptions!C68 -> 8545 | D9: =C9-Pro_Forma_IS!C30+Pro_Forma_CF!C19*-1 -> 8063.5 | E9: =D9-Pro_Forma_IS!D30+Pro_Forma_CF!D19*-1 -> 7559.35 | F9: =E9-Pro_Forma_IS!E30+Pro_Forma_CF!E19*-1 -> 7031.3425 | G9: =F9-Pro_Forma_IS!F30+Pro_Forma_CF!F19*-1 -> 6478.2096 | H9: =G9-Pro_Forma_IS!G30+Pro_Forma_CF!G19*-1 -> 5897.1201
B10: Goodwill | C10: =Assumptions!C18+Transaction_Summary!C22 -> 1951.875 | D10: =C10 -> 1951.875 | E10: =D10 -> 1951.875 | F10: =E10 -> 1951.875 | G10: =F10 -> 1951.875 | H10: =G10 -> 1951.875
B11: Intangibles (net | C11: =Transaction_Summary!C19 -> 337.5 | D11: =C11-Pro_Forma_IS!C31 -> 303.75 | E11: =D11-Pro_Forma_IS!D31 -> 270 | F11: =E11-Pro_Forma_IS!E31 -> 236.25 | G11: =F11-Pro_Forma_IS!F31 -> 202.5 | H11: =G11-Pro_Forma_IS!G31 -> 168.75
B12: Tangible Step-Up (subsumed in GW | C12: 0 | D12: 0 | E12: 0 | F12: 0 | G12: 0 | H12: 0
B13: Deal Asset (Advisory | C13: =Assumptions!C36 -> 65 | D13: =MAX(0,C13-Pro_Forma_IS!C40) -> 0 | E13: =MAX(0,D13-Pro_Forma_IS!D40) -> 0 | F13: =MAX(0,E13-Pro_Forma_IS!E40) -> 0 | G13: =MAX(0,F13-Pro_Forma_IS!F40) -> 0 | H13: =MAX(0,G13-Pro_Forma_IS!G40) -> 0
B14: Financing Fee Asset (net | C14: =Assumptions!C37 -> 50 | D14: =MAX(0,C14-Pro_Forma_IS!C41) -> 42.857143 | E14: =MAX(0,D14-Pro_Forma_IS!D41) -> 35.714286 | F14: =MAX(0,E14-Pro_Forma_IS!E41) -> 28.571429 | G14: =MAX(0,F14-Pro_Forma_IS!F41) -> 21.428571 | H14: =MAX(0,G14-Pro_Forma_IS!G41) -> 14.285714
B16: TOTAL ASSETS | C16: =SUM(C8:C14) -> 10949.375 | D16: =SUM(D8:D14) -> 16630.258 | E16: =SUM(E8:E14) -> 22685.154 | F16: =SUM(F8:F14) -> 29167.12 | G16: =SUM(G8:G14) -> 36033.003 | H16: =SUM(H8:H14) -> 43270.51
B17: Liabilities & Equity
B18: New Acquisition Debt | C18: =Assumptions!C91 -> -35 | D18: =Credit_Metrics!C11 -> 0 | E18: =Credit_Metrics!D11 -> 3.5 | F18: =Credit_Metrics!E11 -> 7 | G18: =Credit_Metrics!F11 -> 10.5 | H18: =Credit_Metrics!G11 -> 14
B19: Acquirer Existing Debt | C19: =Assumptions!C15 -> 5000 | D19: =Credit_Metrics!C17 -> 4750 | E19: =Credit_Metrics!D17 -> 4512.5 | F19: =Credit_Metrics!E17 -> 4286.875 | G19: =Credit_Metrics!F17 -> 4072.5312 | H19: =Credit_Metrics!G17 -> 3868.9047
B20: Other Liabilities | C20: =Assumptions!C19 -> 2000 | D20: =Assumptions!C19 -> 2000 | E20: =Assumptions!C19 -> 2000 | F20: =Assumptions!C19 -> 2000 | G20: =Assumptions!C19 -> 2000 | H20: =Assumptions!C19 -> 2000
B21: Deferred Tax Liability | C21: =Transaction_Summary!C21 -> 84.375 | D21: =Transaction_Summary!C21 -> 84.375 | E21: =Transaction_Summary!C21 -> 84.375 | F21: =Transaction_Summary!C21 -> 84.375 | G21: =Transaction_Summary!C21 -> 84.375 | H21: =Transaction_Summary!C21 -> 84.375
B23: Total Liabilities | C23: =SUM(C18:C21) -> 7049.375 | D23: =SUM(D18:D21) -> 6834.375 | E23: =SUM(E18:E21) -> 6600.375 | F23: =SUM(F18:F21) -> 6378.25 | G23: =SUM(G18:G21) -> 6167.4062 | H23: =SUM(H18:H21) -> 5967.2797
B25: Equity | C25: =Assumptions!C20+Assumptions!C89 -> 3900 | D25: =Credit_Metrics!C42 -> 9795.8833 | E25: =Credit_Metrics!D42 -> 16084.779 | F25: =Credit_Metrics!E42 -> 22788.87 | G25: =Credit_Metrics!F42 -> 29865.597 | H25: =Credit_Metrics!G42 -> 37303.231
B27: TOTAL L&E | C27: =C23+C25 -> 10949.375 | D27: =D23+D25 -> 16630.258 | E27: =E23+E25 -> 22685.154 | F27: =F23+F25 -> 29167.12 | G27: =G23+G25 -> 36033.003 | H27: =H23+H25 -> 43270.51
B29: Check | C29: =C16-C27 -> 0 | D29: =D16-D27 -> 0 | E29: =E16-E27 -> 0 | F29: =F16-F27 -> 0 | G29: =G16-G27 -> 0 | H29: =H16-H27 -> 0

Sheet Pro_Forma_CF
B2: Pro Forma Cash Flow Statement
B3: 5-year — ties to BS cash
B6: $M | C6: Year 1 | D6: Year 2 | E6: Year 3 | F6: Year 4 | G6: Year 5
B7: Operating Section
B8: Net Income | C8: =Pro_Forma_IS!C48 -> 7369.8541 | D8: =Pro_Forma_IS!D48 -> 7861.1193 | E8: =Pro_Forma_IS!E48 -> 8380.1146 | F8: =Pro_Forma_IS!F48 -> 8845.9085 | G8: =Pro_Forma_IS!G48 -> 9297.042
B9: + D&A (combined | C9: =Pro_Forma_IS!C30 -> 1936.86 | D9: =Pro_Forma_IS!D30 -> 2033.8488 | E9: =Pro_Forma_IS!E30 -> 2135.6987 | F9: =Pro_Forma_IS!F30 -> 2242.6537 | G9: =Pro_Forma_IS!G30 -> 2354.9701
B10: + PPA Amort | C10: =Pro_Forma_IS!C31 -> 33.75 | D10: =Pro_Forma_IS!D31 -> 33.75 | E10: =Pro_Forma_IS!E31 -> 33.75 | F10: =Pro_Forma_IS!F31 -> 33.75 | G10: =Pro_Forma_IS!G31 -> 33.75
B11: + Tangible Step-Up Amort | C11: =Pro_Forma_IS!C32 -> 0 | D11: =Pro_Forma_IS!D32 -> 0 | E11: =Pro_Forma_IS!E32 -> 0 | F11: =Pro_Forma_IS!F32 -> 0 | G11: =Pro_Forma_IS!G32 -> 0
B12: + Financing Fee Amort | C12: =Pro_Forma_IS!C41 -> 7.1428571 | D12: =Pro_Forma_IS!D41 -> 7.1428571 | E12: =Pro_Forma_IS!E41 -> 7.1428571 | F12: =Pro_Forma_IS!F41 -> 7.1428571 | G12: =Pro_Forma_IS!G41 -> 7.1428571
B13: + Txn Fee Amort (non-cash | C13: =Pro_Forma_IS!C40 -> 65 | D13: =Pro_Forma_IS!D40 -> 0 | E13: =Pro_Forma_IS!E40 -> 0 | F13: =Pro_Forma_IS!F40 -> 0 | G13: =Pro_Forma_IS!G40 -> 0
B14: ΔWorking Capital | C14: =0 -> 0 | D14: =0 -> 0 | E14: =0 -> 0 | F14: =0 -> 0 | G14: =0 -> 0
B16: Cash from Operations | C16: =SUM(C8:C14) -> 9412.607 | D16: =SUM(D8:D14) -> 9935.8609 | E16: =SUM(E8:E14) -> 10556.706 | F16: =SUM(F8:F14) -> 11129.455 | G16: =SUM(G8:G14) -> 11692.905
B17: Investing Section
B18: Deal-Related Investing | C18: =0 -> 0 | D18: =0 -> 0 | E18: =0 -> 0 | F18: =0 -> 0 | G18: =0 -> 0
B19: Maintenance Capex | C19: =-Pro_Forma_IS!C26*Assumptions!C76 -> -1455.36 | D19: =-Pro_Forma_IS!D26*Assumptions!C76 -> -1529.6988 | E19: =-Pro_Forma_IS!E26*Assumptions!C76 -> -1607.6912 | F19: =-Pro_Forma_IS!F26*Assumptions!C76 -> -1689.5208 | G19: =-Pro_Forma_IS!G26*Assumptions!C76 -> -1773.8805
B21: Cash from Investing | C21: =C18+C19 -> -1455.36 | D21: =D18+D19 -> -1529.6988 | E21: =E18+E19 -> -1607.6912 | F21: =F18+F19 -> -1689.5208 | G21: =G18+G19 -> -1773.8805
B22: Financing Section
B23: New Debt Amortisation | C23: =Credit_Metrics!C9 -> 35 | D23: =Credit_Metrics!D9 -> 3.5 | E23: =Credit_Metrics!E9 -> 3.5 | F23: =Credit_Metrics!F9 -> 3.5 | G23: =Credit_Metrics!G9 -> 3.5
B24: New Debt Balloon | C24: =Credit_Metrics!C10 -> 0 | D24: =Credit_Metrics!D10 -> 0 | E24: =Credit_Metrics!E10 -> 0 | F24: =Credit_Metrics!F10 -> 0 | G24: =Credit_Metrics!G10 -> 0
B25: Acquirer Debt Amortisation | C25: =Credit_Metrics!C16 -> -250 | D25: =Credit_Metrics!D16 -> -237.5 | E25: =Credit_Metrics!E16 -> -225.625 | F25: =Credit_Metrics!F16 -> -214.34375 | G25: =Credit_Metrics!G16 -> -203.62656
B26: Cash to Shareholders | C26: =-Credit_Metrics!C41 -> -1473.9708 | D26: =-Credit_Metrics!D41 -> -1572.2239 | E26: =-Credit_Metrics!E41 -> -1676.0229 | F26: =-Credit_Metrics!F41 -> -1769.1817 | G26: =-Credit_Metrics!G41 -> -1859.4084
B28: Cash from Financing | C28: =C23+C24+C25+C26 -> -1688.9708 | D28: =D23+D24+D25+D26 -> -1806.2239 | E28: =E23+E24+E25+E26 -> -1898.1479 | F28: =F23+F24+F25+F26 -> -1980.0254 | G28: =G23+G24+G25+G26 -> -2059.535
B30: Net Δ Cash | C30: =C16+C21+C28 -> 6268.2761 | D30: =D16+D21+D28 -> 6599.9383 | E30: =E16+E21+E28 -> 7050.8671 | F30: =F16+F21+F28 -> 7459.9088 | G30: =G16+G21+G28 -> 7859.4894
B31: Opening Cash | C31: =Pro_Forma_BS!C8 -> 0 | D31: =C32 -> 6268.2761 | E31: =D32 -> 12868.214 | F31: =E32 -> 19919.081 | G31: =F32 -> 27378.99
B32: CLOSING CASH | C32: =C31+C30 -> 6268.2761 | D32: =D31+D30 -> 12868.214 | E32: =E31+E30 -> 19919.081 | F32: =F31+F30 -> 27378.99 | G32: =G31+G30 -> 35238.48

Sheet Standalone_IS
B2: Standalone Income Statement
B3: Acquirer Only (counterfactual
B6: $M | C6: Year 1 | D6: Year 2 | E6: Year 3 | F6: Year 4 | G6: Year 5
B8: Revenue | C8: =Assumptions!C6*(1+Assumptions!C7)^1 -> 48300 | D8: =Assumptions!C6*(1+Assumptions!C7)^2 -> 50715 | E8: =Assumptions!C6*(1+Assumptions!C7)^3 -> 53250.75 | F8: =Assumptions!C6*(1+Assumptions!C7)^4 -> 55913.287 | G8: =Assumptions!C6*(1+Assumptions!C7)^5 -> 58708.952
B9: EBITDA | C9: =C8*Assumptions!C8 -> 12075 | D9: =D8*Assumptions!C8 -> 12678.75 | E9: =E8*Assumptions!C8 -> 13312.688 | F9: =F8*Assumptions!C8 -> 13978.322 | G9: =G8*Assumptions!C8 -> 14677.238
B10: D&A | C10: =C8*Assumptions!C9 -> 1932 | D10: =D8*Assumptions!C9 -> 2028.6 | E10: =E8*Assumptions!C9 -> 2130.03 | F10: =F8*Assumptions!C9 -> 2236.5315 | G10: =G8*Assumptions!C9 -> 2348.3581
B11: EBIT | C11: =C9-C10 -> 10143 | D11: =D9-D10 -> 10650.15 | E11: =E9-E10 -> 11182.658 | F11: =F9-F10 -> 11741.79 | G11: =G9-G10 -> 12328.88
B14: Interest Expense | C14: =Credit_Metrics!C18 -> 200 | D14: =Credit_Metrics!D18 -> 190 | E14: =Credit_Metrics!E18 -> 180.5 | F14: =Credit_Metrics!F18 -> 171.475 | G14: =Credit_Metrics!G18 -> 162.90125
B16: EBT | C16: =C11-C14 -> 9943 | D16: =D11-D14 -> 10460.15 | E16: =E11-E14 -> 11002.158 | F16: =F11-F14 -> 11570.315 | G16: =G11-G14 -> 12165.979
B17: Tax | C17: =C16*Assumptions!C12 -> 2485.75 | D17: =D16*Assumptions!C12 -> 2615.0375 | E17: =E16*Assumptions!C12 -> 2750.5394 | F17: =F16*Assumptions!C12 -> 2892.5788 | G17: =G16*Assumptions!C12 -> 3041.4947
B19: STANDALONE NET INCOME | C19: =C16-C17 -> 7457.25 | D19: =D16-D17 -> 7845.1125 | E19: =E16-E17 -> 8251.6181 | F19: =F16-F17 -> 8677.7365 | G19: =G16-G17 -> 9124.484
B21: Standalone EPS | C21: =C19/Assumptions!C14 -> 22.597727 | D21: =D19/Assumptions!C14 -> 23.773068 | E21: =E19/Assumptions!C14 -> 25.004903 | F21: =F19/Assumptions!C14 -> 26.296171 | G21: =G19/Assumptions!C14 -> 27.649951

Sheet Accretion_Dilution
B2: Accretion / Dilution Analysis
B3: EPS comparison + $ and $/share bridges
C6: Year 1 | D6: Year 2 | E6: Year 3 | F6: Year 4 | G6: Year 5
B7: EPS Comparison
B8: Standalone EPS | C8: =Standalone_IS!C21 -> 22.597727 | D8: =Standalone_IS!D21 -> 23.773068 | E8: =Standalone_IS!E21 -> 25.004903 | F8: =Standalone_IS!F21 -> 26.296171 | G8: =Standalone_IS!G21 -> 27.649951
B9: Pro Forma EPS | C9: =Pro_Forma_IS!C50 -> 22.198356 | D9: =Pro_Forma_IS!D50 -> 23.67807 | E9: =Pro_Forma_IS!E50 -> 25.241309 | F9: =Pro_Forma_IS!F50 -> 26.644303 | G9: =Pro_Forma_IS!G50 -> 28.003139
B11: Accretion / (Dilution) $ | C11: =C9-C8 -> -0.39937153 | D11: =D9-D8 -> -0.09499813 | E11: =E9-E8 -> 0.23640568 | F11: =F9-F8 -> 0.34813138 | G11: =G9-G8 -> 0.35318708
B12: Accretion / (Dilution) % | C12: =IF(C8=0,0,C11/C8) -> -0.017673084 | D12: =IF(D8=0,0,D11/D8) -> -0.0039960399 | E12: =IF(E8=0,0,E11/E8) -> 0.009454373 | F12: =IF(F8=0,0,F11/F8) -> 0.013238862 | G12: =IF(G8=0,0,G11/G8) -> 0.012773515
B14: $ Contribution Analysis (NI Bridge
B15: Target Net Earnings | C15: =(Assumptions!C23*(1+Assumptions!C24)^1*Assumptions!C25-Assumptions!C23*(1+Assumptions!C24)^1*Assumptions!C26)*(1-Assumptions!C12) -> 44.955 | D15: =(Assumptions!C23*(1+Assumptions!C24)^2*Assumptions!C25-Assumptions!C23*(1+Assumptions!C24)^2*Assumptions!C26)*(1-Assumptions!C12) -> 48.5514 | E15: =(Assumptions!C23*(1+Assumptions!C24)^3*Assumptions!C25-Assumptions!C23*(1+Assumptions!C24)^3*Assumptions!C26)*(1-Assumptions!C12) -> 52.435512 | F15: =(Assumptions!C23*(1+Assumptions!C24)^4*Assumptions!C25-Assumptions!C23*(1+Assumptions!C24)^4*Assumptions!C26)*(1-Assumptions!C12) -> 56.630353 | G15: =(Assumptions!C23*(1+Assumptions!C24)^5*Assumptions!C25-Assumptions!C23*(1+Assumptions!C24)^5*Assumptions!C26)*(1-Assumptions!C12) -> 61.160781
B16: + Revenue Synergies | C16: =Pro_Forma_IS!C21*(1-Assumptions!C12) -> 7.5 | D16: =Pro_Forma_IS!D21*(1-Assumptions!C12) -> 15 | E16: =Pro_Forma_IS!E21*(1-Assumptions!C12) -> 22.5 | F16: =Pro_Forma_IS!F21*(1-Assumptions!C12) -> 30 | G16: =Pro_Forma_IS!G21*(1-Assumptions!C12) -> 30
B17: + Cost Synergies | C17: =Pro_Forma_IS!C22*(1-Assumptions!C12) -> 28.125 | D17: =Pro_Forma_IS!D22*(1-Assumptions!C12) -> 56.25 | E17: =Pro_Forma_IS!E22*(1-Assumptions!C12) -> 84.375 | F17: =Pro_Forma_IS!F22*(1-Assumptions!C12) -> 112.5 | G17: =Pro_Forma_IS!G22*(1-Assumptions!C12) -> 112.5
B18: − Integration Costs | C18: =Pro_Forma_IS!C28*(1-Assumptions!C12) -> -56.25 | D18: =Pro_Forma_IS!D28*(1-Assumptions!C12) -> -56.25 | E18: =Pro_Forma_IS!E28*(1-Assumptions!C12) -> 0 | F18: =Pro_Forma_IS!F28*(1-Assumptions!C12) -> 0 | G18: =Pro_Forma_IS!G28*(1-Assumptions!C12) -> 0
B19: − PPA Amort | C19: =-Pro_Forma_IS!C31*(1-Assumptions!C12) -> -25.3125 | D19: =-Pro_Forma_IS!D31*(1-Assumptions!C12) -> -25.3125 | E19: =-Pro_Forma_IS!E31*(1-Assumptions!C12) -> -25.3125 | F19: =-Pro_Forma_IS!F31*(1-Assumptions!C12) -> -25.3125 | G19: =-Pro_Forma_IS!G31*(1-Assumptions!C12) -> -25.3125
B20: − Tangible Step-Up Amort | C20: =-Pro_Forma_IS!C32*(1-Assumptions!C12) -> 0 | D20: =-Pro_Forma_IS!D32*(1-Assumptions!C12) -> 0 | E20: =-Pro_Forma_IS!E32*(1-Assumptions!C12) -> 0 | F20: =-Pro_Forma_IS!F32*(1-Assumptions!C12) -> 0 | G20: =-Pro_Forma_IS!G32*(1-Assumptions!C12) -> 0
B21: − New Debt Interest | C21: =-Pro_Forma_IS!C38*(1-Assumptions!C12) -> 1.44375 | D21: =-Pro_Forma_IS!D38*(1-Assumptions!C12) -> 0 | E21: =-Pro_Forma_IS!E38*(1-Assumptions!C12) -> -0.144375 | F21: =-Pro_Forma_IS!F38*(1-Assumptions!C12) -> -0.28875 | G21: =-Pro_Forma_IS!G38*(1-Assumptions!C12) -> -0.433125
B22: − Foregone Cash Interest | C22: =-Pro_Forma_IS!C42*(1-Assumptions!C12) -> -33.75 | D22: =-Pro_Forma_IS!D42*(1-Assumptions!C12) -> -16.875 | E22: =-Pro_Forma_IS!E42*(1-Assumptions!C12) -> 0 | F22: =-Pro_Forma_IS!F42*(1-Assumptions!C12) -> 0 | G22: =-Pro_Forma_IS!G42*(1-Assumptions!C12) -> 0
B23: − Transaction Fees | C23: =-Pro_Forma_IS!C40*(1-Assumptions!C12) -> -48.75 | D23: =-Pro_Forma_IS!D40*(1-Assumptions!C12) -> 0 | E23: =-Pro_Forma_IS!E40*(1-Assumptions!C12) -> 0 | F23: =-Pro_Forma_IS!F40*(1-Assumptions!C12) -> 0 | G23: =-Pro_Forma_IS!G40*(1-Assumptions!C12) -> 0
B24: − Financing Fee Amort | C24: =-Pro_Forma_IS!C41*(1-Assumptions!C12) -> -5.3571429 | D24: =-Pro_Forma_IS!D41*(1-Assumptions!C12) -> -5.3571429 | E24: =-Pro_Forma_IS!E41*(1-Assumptions!C12) -> -5.3571429 | F24: =-Pro_Forma_IS!F41*(1-Assumptions!C12) -> -5.3571429 | G24: =-Pro_Forma_IS!G41*(1-Assumptions!C12) -> -5.3571429
B26: Net NI Contribution | C26: =SUM(C15:C24) -> -87.395893 | D26: =SUM(D15:D24) -> 16.006757 | E26: =SUM(E15:E24) -> 128.49649 | F26: =SUM(F15:F24) -> 168.17196 | G26: =SUM(G15:G24) -> 172.55801
B27: Bridge Tie (must = 0 | C27: =C26-C28 -> 1.7905677e-12 | D27: =D26-D28 -> -1.8438584e-12 | E27: =E26-E28 -> -1.7053026e-12 | F27: =F26-F28 -> 2.7284841e-12 | G27: =G26-G28 -> -7.3896445e-13
B28: PF_NI − SA_NI (reference | C28: =Pro_Forma_IS!C48-Standalone_IS!C19 -> -87.395893 | D28: =Pro_Forma_IS!D48-Standalone_IS!D19 -> 16.006757 | E28: =Pro_Forma_IS!E48-Standalone_IS!E19 -> 128.49649 | F28: =Pro_Forma_IS!F48-Standalone_IS!F19 -> 168.17196 | G28: =Pro_Forma_IS!G48-Standalone_IS!G19 -> 172.55801
B30: $/share EPS Bridge
B32: Standalone EPS | C32: =Standalone_IS!C21 -> 22.597727 | D32: =Standalone_IS!D21 -> 23.773068 | E32: =Standalone_IS!E21 -> 25.004903 | F32: =Standalone_IS!F21 -> 26.296171 | G32: =Standalone_IS!G21 -> 27.649951
B33: + Target Earnings / PF Shares | C33: =C15/Assumptions!C92 -> 0.13540663 | D33: =D15/Assumptions!C92 -> 0.14623916 | E33: =E15/Assumptions!C92 -> 0.15793829 | F33: =F15/Assumptions!C92 -> 0.17057335 | G33: =G15/Assumptions!C92 -> 0.18421922
B34: + Revenue Synergies / PF Shares | C34: =C16/Assumptions!C92 -> 0.022590361 | D34: =D16/Assumptions!C92 -> 0.045180723 | E34: =E16/Assumptions!C92 -> 0.067771084 | F34: =F16/Assumptions!C92 -> 0.090361446 | G34: =G16/Assumptions!C92 -> 0.090361446
B35: + Cost Synergies / PF Shares | C35: =C17/Assumptions!C92 -> 0.084713855 | D35: =D17/Assumptions!C92 -> 0.16942771 | E35: =E17/Assumptions!C92 -> 0.25414157 | F35: =F17/Assumptions!C92 -> 0.33885542 | G35: =G17/Assumptions!C92 -> 0.33885542
B36: − Integration / PF Shares | C36: =C18/Assumptions!C92 -> -0.16942771 | D36: =D18/Assumptions!C92 -> -0.16942771 | E36: =E18/Assumptions!C92 -> 0 | F36: =F18/Assumptions!C92 -> 0 | G36: =G18/Assumptions!C92 -> 0
B37: − PPA Amort / PF Shares | C37: =C19/Assumptions!C92 -> -0.07624247 | D37: =D19/Assumptions!C92 -> -0.07624247 | E37: =E19/Assumptions!C92 -> -0.07624247 | F37: =F19/Assumptions!C92 -> -0.07624247 | G37: =G19/Assumptions!C92 -> -0.07624247
B38: − Tangible Step-Up / PF Shares | C38: =C20/Assumptions!C92 -> 0 | D38: =D20/Assumptions!C92 -> 0 | E38: =E20/Assumptions!C92 -> 0 | F38: =F20/Assumptions!C92 -> 0 | G38: =G20/Assumptions!C92 -> 0
B39: − New Debt Int / PF Shares | C39: =C21/Assumptions!C92 -> 0.0043486446 | D39: =D21/Assumptions!C92 -> 0 | E39: =E21/Assumptions!C92 -> -0.00043486446 | F39: =F21/Assumptions!C92 -> -0.00086972892 | G39: =G21/Assumptions!C92 -> -0.0013045934
B40: − Foregone Int / PF Shares | C40: =C22/Assumptions!C92 -> -0.10165663 | D40: =D22/Assumptions!C92 -> -0.050828313 | E40: =E22/Assumptions!C92 -> 0 | F40: =F22/Assumptions!C92 -> 0 | G40: =G22/Assumptions!C92 -> 0
B41: − Txn Fees / PF Shares | C41: =C23/Assumptions!C92 -> -0.14683735 | D41: =D23/Assumptions!C92 -> 0 | E41: =E23/Assumptions!C92 -> 0 | F41: =F23/Assumptions!C92 -> 0 | G41: =G23/Assumptions!C92 -> 0
B42: − Fin Fee Amort / PF Shares | C42: =C24/Assumptions!C92 -> -0.016135972 | D42: =D24/Assumptions!C92 -> -0.016135972 | E42: =E24/Assumptions!C92 -> -0.016135972 | F42: =F24/Assumptions!C92 -> -0.016135972 | G42: =G24/Assumptions!C92 -> -0.016135972
B43: − Share Dilution Drag | C43: =Standalone_IS!C19/Assumptions!C92-Standalone_IS!C21 -> -0.13613089 | D43: =Standalone_IS!D19/Assumptions!C92-Standalone_IS!D21 -> -0.14321125 | E43: =Standalone_IS!E19/Assumptions!C92-Standalone_IS!E21 -> -0.15063195 | F43: =Standalone_IS!F19/Assumptions!C92-Standalone_IS!F21 -> -0.15841067 | G43: =Standalone_IS!G19/Assumptions!C92-Standalone_IS!G21 -> -0.16656597
B45: Pro Forma EPS (bridge sum | C45: =SUM(C32:C43) -> 22.198356 | D45: =SUM(D32:D43) -> 23.67807 | E45: =SUM(E32:E43) -> 25.241309 | F45: =SUM(F32:F43) -> 26.644303 | G45: =SUM(G32:G43) -> 28.003139
B46: Bridge Tie ($/share, must = 0 | C46: =C45-Pro_Forma_IS!C50 -> 0 | D46: =D45-Pro_Forma_IS!D50 -> 0 | E46: =E45-Pro_Forma_IS!E50 -> 0 | F46: =F45-Pro_Forma_IS!F50 -> 0 | G46: =G45-Pro_Forma_IS!G50 -> 0

Sheet Credit_Metrics
B2: Credit Metrics
B3: Debt Schedule + Leverage & Coverage
B6: $M | C6: Year 1 | D6: Year 2 | E6: Year 3 | F6: Year 4 | G6: Year 5
B7: Acquisition Debt
B8: Opening Balance | C8: =Assumptions!C91 -> -35 | D8: =C11 -> 0 | E8: =D11 -> 3.5 | F8: =E11 -> 7 | G8: =F11 -> 10.5
B9: Amortisation | C9: =-MIN(C8,Assumptions!C91*Assumptions!C45) -> 35 | D9: =-MIN(D8,(Assumptions!C91*Assumptions!C45)) -> 3.5 | E9: =-MIN(E8,(Assumptions!C91*Assumptions!C45)) -> 3.5 | F9: =-MIN(F8,(Assumptions!C91*Assumptions!C45)) -> 3.5 | G9: =-MIN(G8,(Assumptions!C91*Assumptions!C45)) -> 3.5
B10: Balloon Repayment | C10: =IF(1=Assumptions!C44,-(C8+C9),0) -> 0 | D10: =IF(2=Assumptions!C44,-(D8+D9),0) -> 0 | E10: =IF(3=Assumptions!C44,-(E8+E9),0) -> 0 | F10: =IF(4=Assumptions!C44,-(F8+F9),0) -> 0 | G10: =IF(5=Assumptions!C44,-(G8+G9),0) -> 0
B11: Closing Balance | C11: =C8+C9+C10 -> 0 | D11: =D8+D9+D10 -> 3.5 | E11: =E8+E9+E10 -> 7 | F11: =F8+F9+F10 -> 10.5 | G11: =G8+G9+G10 -> 14
B12: Interest Expense | C12: =C8*Assumptions!C43 -> -1.925 | D12: =D8*Assumptions!C43 -> 0 | E12: =E8*Assumptions!C43 -> 0.1925 | F12: =F8*Assumptions!C43 -> 0.385 | G12: =G8*Assumptions!C43 -> 0.5775
B14: Acquirer Existing Debt
B15: Opening Balance | C15: =Assumptions!C15 -> 5000 | D15: =C17 -> 4750 | E15: =D17 -> 4512.5 | F15: =E17 -> 4286.875 | G15: =F17 -> 4072.5312
B16: Amortisation | C16: =-C15*Assumptions!C11 -> -250 | D16: =-D15*Assumptions!C11 -> -237.5 | E16: =-E15*Assumptions!C11 -> -225.625 | F16: =-F15*Assumptions!C11 -> -214.34375 | G16: =-G15*Assumptions!C11 -> -203.62656
B17: Closing Balance | C17: =C15+C16 -> 4750 | D17: =D15+D16 -> 4512.5 | E17: =E15+E16 -> 4286.875 | F17: =F15+F16 -> 4072.5312 | G17: =G15+G16 -> 3868.9047
B18: Interest Expense | C18: =C15*(Assumptions!C10/Assumptions!C15) -> 200 | D18: =D15*(Assumptions!C10/Assumptions!C15) -> 190 | E18: =E15*(Assumptions!C10/Assumptions!C15) -> 180.5 | F18: =F15*(Assumptions!C10/Assumptions!C15) -> 171.475 | G18: =G15*(Assumptions!C10/Assumptions!C15) -> 162.90125
B20: Total Debt
B21: TOTAL DEBT | C21: =C11+C17 -> 4750 | D21: =D11+D17 -> 4516 | E21: =E11+E17 -> 4293.875 | F21: =F11+F17 -> 4083.0312 | G21: =G11+G17 -> 3882.9047
B22: Total Debt-Schedule Interest | C22: =C12+C18 -> 198.075 | D22: =D12+D18 -> 190 | E22: =E12+E18 -> 180.6925 | F22: =F12+F18 -> 171.86 | G22: =G12+G18 -> 163.47875
B24: Leverage Ratios
B25: Combined EBITDA | C25: =Pro_Forma_IS!C27 -> 12187.3 | D25: =Pro_Forma_IS!D27 -> 12843.734 | E25: =Pro_Forma_IS!E27 -> 13530.77 | F25: =Pro_Forma_IS!F27 -> 14249.951 | G25: =Pro_Forma_IS!G27 -> 14955.398
B27: Debt / EBITDA | C27: =IF(C25=0,0,C21/C25) -> 0.38974999 | D27: =IF(D25=0,0,D21/D25) -> 0.35161114 | E27: =IF(E25=0,0,E21/E25) -> 0.31734151 | F27: =IF(F25=0,0,F21/F25) -> 0.28652949 | G27: =IF(G25=0,0,G21/G25) -> 0.25963233
B28: Interest Coverage (EBITDA/Int | C28: =IF(Pro_Forma_IS!C39=0,0,C25/C22) -> 61.528714 | D28: =IF(Pro_Forma_IS!D39=0,0,D25/D22) -> 67.5986 | E28: =IF(Pro_Forma_IS!E39=0,0,E25/E22) -> 74.882855 | F28: =IF(Pro_Forma_IS!F39=0,0,F25/F22) -> 82.916043 | G28: =IF(Pro_Forma_IS!G39=0,0,G25/G22) -> 91.482212
B30: Pro-forma Equity (market-cap proxy
B31: Opening Equity (proxy | C31: =Assumptions!C13*Assumptions!C14+Assumptions!C89 -> 149400 | D31: =C34 -> 155295.88 | E31: =D34 -> 161584.78 | F31: =E34 -> 168288.87 | G31: =F34 -> 175365.6
B32: Net Income | C32: =Pro_Forma_IS!C48 -> 7369.8541 | D32: =Pro_Forma_IS!D48 -> 7861.1193 | E32: =Pro_Forma_IS!E48 -> 8380.1146 | F32: =Pro_Forma_IS!F48 -> 8845.9085 | G32: =Pro_Forma_IS!G48 -> 9297.042
B33: Dividends Declared | C33: =Pro_Forma_IS!C48*Assumptions!C77 -> 1473.9708 | D33: =Pro_Forma_IS!D48*Assumptions!C77 -> 1572.2239 | E33: =Pro_Forma_IS!E48*Assumptions!C77 -> 1676.0229 | F33: =Pro_Forma_IS!F48*Assumptions!C77 -> 1769.1817 | G33: =Pro_Forma_IS!G48*Assumptions!C77 -> 1859.4084
B34: Closing Equity (proxy | C34: =C31+C32-C33 -> 155295.88 | D34: =D31+D32-D33 -> 161584.78 | E34: =E31+E32-E33 -> 168288.87 | F34: =F31+F32-F33 -> 175365.6 | G34: =G31+G32-G33 -> 182803.23
B36: Debt / Equity (proxy | C36: =IF(C34<=0,"N/A",C21/C34) -> 0.030586773 | D36: =IF(D34<=0,"N/A",D21/D34) -> 0.027948177 | E36: =IF(E34<=0,"N/A",E21/E34) -> 0.025514908 | F36: =IF(F34<=0,"N/A",F21/F34) -> 0.023282966 | G36: =IF(G34<=0,"N/A",G21/G34) -> 0.021240897
B38: Book Equity (accounting rollforward
B39: Opening Book Equity | C39: =Assumptions!C20+Assumptions!C89 -> 3900 | D39: =C42 -> 9795.8833 | E39: =D42 -> 16084.779 | F39: =E42 -> 22788.87 | G39: =F42 -> 29865.597
B40: + Net Income | C40: =Pro_Forma_IS!C48 -> 7369.8541 | D40: =Pro_Forma_IS!D48 -> 7861.1193 | E40: =Pro_Forma_IS!E48 -> 8380.1146 | F40: =Pro_Forma_IS!F48 -> 8845.9085 | G40: =Pro_Forma_IS!G48 -> 9297.042
B41: Dividends Declared | C41: =Pro_Forma_IS!C48*Assumptions!C77 -> 1473.9708 | D41: =Pro_Forma_IS!D48*Assumptions!C77 -> 1572.2239 | E41: =Pro_Forma_IS!E48*Assumptions!C77 -> 1676.0229 | F41: =Pro_Forma_IS!F48*Assumptions!C77 -> 1769.1817 | G41: =Pro_Forma_IS!G48*Assumptions!C77 -> 1859.4084
B42: Closing Book Equity | C42: =C39+C40-C41 -> 9795.8833 | D42: =D39+D40-D41 -> 16084.779 | E42: =E39+E40-E41 -> 22788.87 | F42: =F39+F40-F41 -> 29865.597 | G42: =G39+G40-G41 -> 37303.231

Sheet Buyer_Returns
B2: Buyer Returns
B3: Equity IRR & break-even
C6: Day 0 | D6: Year 1 | E6: Year 2 | F6: Year 3 | G6: Year 4 | H6: Year 5
B7: Cash flow strip ($M | C7: Equity invested | D7: Dividends | E7: Dividends | F7: Dividends | G7: Dividends | H7: Dividends + Terminal
B8: Buyer Equity CF | C8: =-(Assumptions!C38+Assumptions!C89) -> -2400 | D8: =Pro_Forma_IS!C48*Assumptions!$C$77*$C$21 -> 1465.0915 | E8: =Pro_Forma_IS!D48*Assumptions!$C$77*$C$21 -> 1562.7526 | F8: =Pro_Forma_IS!E48*Assumptions!$C$77*$C$21 -> 1665.9264 | G8: =Pro_Forma_IS!F48*Assumptions!$C$77*$C$21 -> 1758.524 | H8: =Pro_Forma_IS!G48*Assumptions!C77*C21+C13 -> 182757.76
B10: Buyer Equity IRR | C10: =IRR(C8:H8) -> 1.6191631
B11: MOIC | C11: =SUM(D8:H8)/(-C8) -> 78.837522
B13: Y5 Terminal Equity Value (full | C13: =(Exit_EBITDA_Multiple * Y5_EBITDA) - (Y5_New_Debt + Y5_Acq_Debt) + Y5_Cash -> 180909.55
B16: Break-Even Cost Synergies (Y3 = 0%
B17: Cost Synergies ($M | C17: =20*(COLUMN()-3) -> 0 | D17: =20*(COLUMN()-3) -> 20 | E17: =20*(COLUMN()-3) -> 40 | F17: =20*(COLUMN()-3) -> 60 | G17: =20*(COLUMN()-3) -> 80 | H17: =20*(COLUMN()-3) -> 100 | I17: =20*(COLUMN()-3) -> 120 | J17: =20*(COLUMN()-3) -> 140 | ... W17: =20*(COLUMN()-3) -> 400
B18: Y3 Accretion % | C18: =((Base_ProForma_EPS+((C17-Base_Synergy)*Phase_Y3*(1-Tax_Rate))/Total_Shares)/Base_SA_EPS)-1 -> -0.00070929614 | D18: =((Base_ProForma_EPS+((D17-Base_Synergy)*Phase_Y3*(1-Tax_Rate))/Total_Shares)/Base_SA_EPS)-1 -> 0.00064585975 | E18: =((Base_ProForma_EPS+((E17-Base_Synergy)*Phase_Y3*(1-Tax_Rate))/Total_Shares)/Base_SA_EPS)-1 -> 0.0020010156 | F18: =((Base_ProForma_EPS+((F17-Base_Synergy)*Phase_Y3*(1-Tax_Rate))/Total_Shares)/Base_SA_EPS)-1 -> 0.0033561715 | G18: =((Base_ProForma_EPS+((G17-Base_Synergy)*Phase_Y3*(1-Tax_Rate))/Total_Shares)/Base_SA_EPS)-1 -> 0.0047113274 | H18: =((Base_ProForma_EPS+((H17-Base_Synergy)*Phase_Y3*(1-Tax_Rate))/Total_Shares)/Base_SA_EPS)-1 -> 0.0060664833 | I18: =((Base_ProForma_EPS+((I17-Base_Synergy)*Phase_Y3*(1-Tax_Rate))/Total_Shares)/Base_SA_EPS)-1 -> 0.0074216392 | J18: =((Base_ProForma_EPS+((J17-Base_Synergy)*Phase_Y3*(1-Tax_Rate))/Total_Shares)/Base_SA_EPS)-1 -> 0.0087767951 | ... W18: =((Base_ProForma_EPS+((W17-Base_Synergy)*Phase_Y3*(1-Tax_Rate))/Total_Shares)/Base_SA_EPS)-1 -> 0.026393822
B20: Break-Even CS (Y3 % = 0 | C20: =FORECAST(0, C17:D17, C18:D18) -> 10.468111 | D20: $M cost synergies needed for Y3 = 0%
B21: Buyer Ownership % (Acquirer shares ÷ Pro Forma shares) | C21: =Assumptions!C14/Assumptions!C92 -> 0.9939759
B23: IRR Lower Bound (diagnostic | C23: 0.05
B24: IRR Upper Bound (diagnostic | C24: 0.3

Sheet Sensitivity
B2: Sensitivity Analysis
B3: Year-3 EPS Accretion %
B6: Premium vs Cost Synergies
B8: =Accretion_Dilution!E12 -> 0.009454373 | C8: 0.1 | D8: 0.15 | E8: 0.2 | F8: 0.25 | G8: 0.3 | I8: Cost Synergy | J8: 150
B9: 100 | C9: 0.0070798887 | D9: 0.006741924 | E9: 0.0064041223 | F9: 0.0060664833 | G9: 0.0056440592 | I9: Offer Premium | J9: 0.25
B10: 125 | C10: 0.008775059 | D10: 0.0084366856 | E10: 0.0080984754 | F10: 0.0077604282 | G10: 0.007337596 | I10: Cash Mix | J10: 0.6
B11: 150 | C11: 0.010470229 | D11: 0.010131447 | E11: 0.0097928286 | F11: 0.009454373 | G11: 0.0090311328
B12: 175 | C12: 0.0121654 | D12: 0.011826209 | E12: 0.011487182 | F12: 0.011148318 | G12: 0.01072467
B13: 200 | C13: 0.01386057 | D13: 0.01352097 | E13: 0.013181535 | F13: 0.012842263 | G13: 0.012418206
B16: Premium vs Cash Mix
B18: =Accretion_Dilution!E12 -> 0.009454373 | C18: 0.4 | D18: 0.5 | E18: 0.6 | F18: 0.7 | G18: 0.8
B19: 0.15 | C19: 0.0071334381 | D19: 0.0086303676 | E19: 0.010131447 | F19: 0.01134995 | G19: 0.011930255
B20: 0.2 | C20: 0.0066665754 | D20: 0.0082274448 | E20: 0.0097928286 | F20: 0.010793841 | G20: 0.011398497
B21: 0.25 | C21: 0.0062000493 | D21: 0.0078247643 | E21: 0.009454373 | F21: 0.010237933 | G21: 0.010866867
B22: 0.3 | C22: 0.0057338592 | D22: 0.007422326 | E22: 0.0090311328 | F22: 0.0096822269 | G22: 0.010335366
B23: 0.35 | C23: 0.0052680049 | D23: 0.0070201296 | E23: 0.0084516513 | F23: 0.0091267215 | G23: 0.0098039939

Sheet Checks
B2: Integrity Checks
B3: Consolidated PASS/FAIL
B6: Check | C6: Result | D6: Value | E6: Tolerance | F6: Notes
B7: Sources − Uses tie | C7: =IF(ABS(D7)<=E7,"PASS","FAIL") -> PASS | D7: =Transaction_Summary!C13 -> 0 | E7: =0.01 -> 0.01 | F7: Sources must equal Uses
B8: PPA Check (independent identity | C8: =IF(ABS(D8)<=E8,"PASS","FAIL") -> PASS | D8: =Transaction_Summary!C24 -> 0 | E8: =0.01 -> 0.01 | F8: Equity_Purchase − (NTA + Step-Up + Intang + GW − DTL − Net Debt) = 0
B9: Bridge Tie Y1 ($ | C9: =IF(ABS(D9)<=E9,"PASS","FAIL") -> PASS | D9: =Accretion_Dilution!C27 -> 1.7905677e-12 | E9: =0.01 -> 0.01 | F9: Net_NI_Contribution − (PF_NI − SA_NI) per year
B10: Bridge Tie Y2 ($ | C10: =IF(ABS(D10)<=E10,"PASS","FAIL") -> PASS | D10: =Accretion_Dilution!D27 -> -1.8438584e-12 | E10: =0.01 -> 0.01
B11: Bridge Tie Y3 ($ | C11: =IF(ABS(D11)<=E11,"PASS","FAIL") -> PASS | D11: =Accretion_Dilution!E27 -> -1.7053026e-12 | E11: =0.01 -> 0.01
B12: Bridge Tie Y4 ($ | C12: =IF(ABS(D12)<=E12,"PASS","FAIL") -> PASS | D12: =Accretion_Dilution!F27 -> 2.7284841e-12 | E12: =0.01 -> 0.01
B13: Bridge Tie Y5 ($ | C13: =IF(ABS(D13)<=E13,"PASS","FAIL") -> PASS | D13: =Accretion_Dilution!G27 -> -7.3896445e-13 | E13: =0.01 -> 0.01
B14: Bridge Tie EPS Y3 ($/share | C14: =IF(ABS(D14)<=E14,"PASS","FAIL") -> PASS | D14: =Accretion_Dilution!E46 -> 0 | E14: =0.01 -> 0.01 | F14: $/share EPS bridge ties to PF_EPS
B15: BS balance Day-1 | C15: =IF(ABS(D15)<=E15,"PASS","FAIL") -> PASS | D15: =Pro_Forma_BS!C29 -> 0 | E15: 0.01 | F15: Assets − L&E
B16: BS balance Y1 | C16: =IF(ABS(D16)<=E16,"PASS","FAIL") -> PASS | D16: =Pro_Forma_BS!D29 -> 0 | E16: 0.01
B17: BS balance Y2 | C17: =IF(ABS(D17)<=E17,"PASS","FAIL") -> PASS | D17: =Pro_Forma_BS!E29 -> 0 | E17: 0.01
B18: BS balance Y3 | C18: =IF(ABS(D18)<=E18,"PASS","FAIL") -> PASS | D18: =Pro_Forma_BS!F29 -> 0 | E18: 0.01
B19: BS balance Y4 | C19: =IF(ABS(D19)<=E19,"PASS","FAIL") -> PASS | D19: =Pro_Forma_BS!G29 -> 0 | E19: 0.01
B20: BS balance Y5 | C20: =IF(ABS(D20)<=E20,"PASS","FAIL") -> PASS | D20: =Pro_Forma_BS!H29 -> 0 | E20: 0.01
B21: Debt schedule continuity | C21: =IF(ABS(D21)<=E21,"PASS","FAIL") -> PASS | D21: =Credit_Metrics!D8-Credit_Metrics!C11 -> 0 | E21: =0.01 -> 0.01 | F21: Y2 opening = Y1 closing
B22: Sensitivity base = Accretion Y3 | C22: =IF(ABS(D22)<=E22,"PASS","FAIL") -> PASS | D22: =Sensitivity!F11-Accretion_Dilution!E12 -> 0 | E22: =0.0001 -> 0.0001 | F22: 30% premium, $150M cost syn
B23: Integration_Phase headroom (must >= 0 | C23: =IF(ABS(D23)<=E23,"PASS","FAIL") -> PASS | D23: =2-(Assumptions!C61+Assumptions!C62+Assumptions!C63+Assumptions!C64+Assumptions!C65) -> 1 | E23: =2 -> 2 | F23: 2.0 − sum(phase weights); negative => exceeds 2× run-rate
B24: Exchange Ratio (must > 0 | C24: =IF(ABS(D24)<=E24,"PASS","FAIL") -> PASS | D24: =Transaction_Summary!C31 -> 0.02 | E24: =100 -> 100 | F24: Acquirer shares per target share — diagnostic only
B25: Buyer return vs lower bound | C25: =IF(ABS(D25)>=E25,"PASS","FAIL") -> PASS | D25: =Buyer_Returns!C10-Buyer_Returns!C23 -> 1.5691631 | E25: =1 -> 1 | F25: Equity return must exceed lower bound (Buyer_Returns!IRR_Lo
B26: Buyer return vs upper bound | C26: =IF(ABS(D26)<=E26,"PASS","FAIL") -> PASS | D26: =Buyer_Returns!C24-Buyer_Returns!C10 -> -1.3191631 | E26: =100 -> 100 | F26: Equity return diagnostic vs upper bound (Buyer_Returns!IRR_Hi
B29: PASS Count | C29: =COUNTIF(C7:C26,"PASS") -> 20
B30: FAIL Count | C30: =COUNTIF(C7:C26,"FAIL") -> 0
