Workbook
Name _INFOSYS: #REF!
Name _INFOSYSLTS: #REF!
Name Accrued_Liab_Pct: [2]Assumptions!$C$75
Name Bad_Debt_Pct: [2]Assumptions!$C$80
Name Benefits_Pct: [2]Assumptions!$C$55
Name Buyback: [2]Assumptions!$C$103
Name CASE: [1]LBO!$E$7
Name CIRC: [1]LBO!$E$6
Name Commit_Fee_Rate: [2]Assumptions!$C$89
Name Deferred_Rev_Pct: [2]Assumptions!$C$79
Name DIO: [2]Assumptions!$C$73
Name Dividend_Payout: [2]Assumptions!$C$99
Name DPO: [2]Assumptions!$C$74
Name DSCR_Floor: [2]Assumptions!$C$91
Name DSO: [2]Assumptions!$C$72
Name Employer_Tax_Pct: [2]Assumptions!$C$54
Name GA_FTE_Base: [2]Assumptions!$C$50
Name GA_FTE_Growth: [2]Assumptions!$C$52
Name GA_NonHead: [2]Assumptions!$C$53
Name GA_Salary: [2]Assumptions!$C$51
Name Growth_CapEx_Pct: [2]Assumptions!$F$67
Name Inflation: [2]Assumptions!$C$41
Name Insurance_Amount: [2]Assumptions!$C$60
Name Insurance_Esc: [2]Assumptions!$C$61
Name Int_Cov_Floor: [2]Assumptions!$C$93
Name Int_Income_Rate: [2]Assumptions!$C$94
Name IQ_CH: 110000
Name IQ_CQ: 5000
Name IQ_CY: 10000
Name IQ_DAILY: 500000
Name IQ_FH: 100000
Name IQ_FQ: 500
Name IQ_FY: 1000
Name IQ_LTM: 2000
Name IQ_MONTH: 15000
Name IQ_NTM: 6000
Name IQ_WEEK: 50000
Name IQ_YTD: 3000
Name Leverage_Ceil: [2]Assumptions!$C$92
Name Maint_CapEx_Pct: [2]Assumptions!$F$66
Name Min_Cash: [2]Assumptions!$C$90
Name Mktg_Pct: [2]Assumptions!$F$57
Name Model_Start_Year: [2]Assumptions!$C$10
Name New_Asset_Life: [2]Assumptions!$C$69
Name New_Debt_Draw: [2]Assumptions!$C$86
Name New_Issuance: [2]Assumptions!$C$102
Name NOL_Opening: [2]Assumptions!$C$98
Name Open_Acc_Depr: [2]Assumptions!$C$113
Name Open_Accrued: [2]Assumptions!$C$115
Name Open_AP: [2]Assumptions!$C$114
Name Open_AR: [2]Assumptions!$C$108
Name Open_Cash: [2]Assumptions!$C$107
Name Open_Deferred_Rev: [2]Assumptions!$C$116
Name Open_Inventory: [2]Assumptions!$C$109
Name Open_Other_CA: [2]Assumptions!$C$111
Name Open_Other_CL: [2]Assumptions!$C$117
Name Open_PPE_Gross: [2]Assumptions!$C$112
Name Open_Prepaid: [2]Assumptions!$C$110
Name Open_Ret_Earnings: [2]Assumptions!$C$123
Name Open_Share_Capital: [2]Assumptions!$C$119

Sheet Dashboard
B2: Dashboard
B3: Headline operating, profitability and cash outputs at a glance | D3: (Values in Crores)
B5: Key Performance Indicators
B6: Revenue | D6: Gross Profit | F6: EBITDA | H6: Net Income | J6: Revenue CAGR
B7: =' Forecasted FS>'!N9 -> 256609.29 | D7: =' Forecasted FS>'!N15 -> 68844.286 | F7: =' Forecasted FS>'!N21 -> 58578.857 | H7: =' Forecasted FS>'!N36 -> 35165.429 | J7: =' Forecasted FS>'!N10 -> 0.062184507
B9: Final year | D9: Final year | F9: Final year | H9: Final year | J9: Yr1-final
B10: Gross Margin | D10: EBITDA Margin | F10: Net Margin | H10: Cash from Ops | J10: Net Δ Cash
B11: =' Forecasted FS>'!N16 -> 0.26828447 | D11: =' Forecasted FS>'!N22 -> 0.22828035 | F11: =' Forecasted FS>'!N37 -> 0.1370388 | H11: =' Forecasted FS>'!N82 -> 49564.091 | J11: =' Forecasted FS>'!N103 -> 5090.482
B13: Final year | D13: Final year | F13: Final year | H13: Final year | J13: Final year
B15: Operating & Cash Flow Summary
B16: Metric | C16: =[2]Income_Statement!C6 -> 2026 | D16: =[2]Income_Statement!D6 -> 2027 | E16: =[2]Income_Statement!E6 -> 2028 | F16: =[2]Income_Statement!F6 -> 2029 | G16: =[2]Income_Statement!G6 -> 2030
B17: Total Revenue | C17: =' Forecasted FS>'!I9 -> 178650 | D17: =' Forecasted FS>'!J9 -> 196517.57 | E17: =' Forecasted FS>'!K9 -> 211540.5 | F17: =' Forecasted FS>'!L9 -> 226563.43 | G17: =' Forecasted FS>'!M9 -> 241586.36
B18: Gross Profit | C18: =' Forecasted FS>'!I15 -> 50393 | D18: =' Forecasted FS>'!J15 -> 54401.429 | E18: =' Forecasted FS>'!K15 -> 58012.143 | F18: =' Forecasted FS>'!L15 -> 61622.857 | G18: =' Forecasted FS>'!M15 -> 65233.571
B19: EBITDA | C19: =' Forecasted FS>'!I21 -> 42280 | D19: =' Forecasted FS>'!J21 -> 46055 | E19: =' Forecasted FS>'!K21 -> 49185.964 | F19: =' Forecasted FS>'!L21 -> 52316.929 | G19: =' Forecasted FS>'!M21 -> 55447.893
B20: Net Income | C20: =' Forecasted FS>'!I36 -> 26441 | D20: =' Forecasted FS>'!J36 -> 27828.714 | E20: =' Forecasted FS>'!K36 -> 29662.893 | F20: =' Forecasted FS>'!L36 -> 31497.071 | G20: =' Forecasted FS>'!M36 -> 33331.25
B21: Net Margin % | C21: =' Forecasted FS>'!I37 -> 0.14800448 | D21: =' Forecasted FS>'!J37 -> 0.14160929 | E21: =' Forecasted FS>'!K37 -> 0.14022323 | F21: =' Forecasted FS>'!L37 -> 0.13902099 | G21: =' Forecasted FS>'!M37 -> 0.13796826
B22: Cash from Operations | C22: =' Forecasted FS>'!I82 -> 33986 | D22: =' Forecasted FS>'!J82 -> 36954.714 | E22: =' Forecasted FS>'!K82 -> 39434.551 | F22: =' Forecasted FS>'!L82 -> 43147.335 | G22: =' Forecasted FS>'!M82 -> 46949.203
B23: Capital Expenditure | C23: =' Forecasted FS>'!I85 -> -2727 | D23: =' Forecasted FS>'!J85 -> -2268.4286 | E23: =' Forecasted FS>'!K85 -> -2507.8163 | F23: =' Forecasted FS>'!L85 -> -2518.0787 | G23: =' Forecasted FS>'!M85 -> -2500.0887
B25: Trend Charts
B39: Revenue Mix (helper
B40: Segment 1 | C40: =[2]Income_Statement!C9 -> 56000000 | D40: =[2]Income_Statement!D9 -> 61600000
B80: Revenue -> Net Income Bridge (final year
B98: Waterfall Chart Data (helper)
B100: Revenue | C100: =0 -> 0 | D100: =' Forecasted FS>'!N9 -> 256609.29
B101: Less: COGS | C101: =D102 -> 68844.286 | D101: =' Forecasted FS>'!N12 -> 187765
B102: Gross Profit | C102: =0 -> 0 | D102: =D100-D101 -> 68844.286
B103: Less: OpEx | C103: =D104 -> 58578.857 | D103: =' Forecasted FS>'!N15-' Forecasted FS>'!N21 -> 10265.429
B104: EBITDA | C104: =0 -> 0 | D104: =D102-D103 -> 58578.857
B105: Less: D&A/Int/Tax | C105: =D106 -> 35165.429 | D105: =' Forecasted FS>'!N21-' Forecasted FS>'!N36 -> 23413.429
B106: Net Income | C106: =0 -> 0 | D106: =D104-D105 -> 35165.429

Sheet  Forecasted FS>
B2: In Crores(Cr.)
B4: ="Historical Financial Statements - "& 'Raw Data Sheet'!B1 -> Historical Financial Statements - INFOSYS LTD
B5: Years | C5: ='Raw Data Sheet'!E16 -> 43921 | D5: =C5+365 -> 44286 | E5: =D5+365 -> 44651 | F5: =E5+365 -> 45016 | G5: =F5+365 -> 45381 | H5: =G5+365 -> 45746 | I5: =H5+365 -> 46111 | J5: =I5+365 -> 46476 | K5: =J5+365 -> 46841 | ... N5: =M5+365 -> 47936
B6: Year Weights | C6: 1 | D6: 2 | E6: 3 | F6: 4 | G6: 5 | H6: 6 | I6: 7 | J6: 8 | K6: 9 | L6: 10 | M6: 11 | N6: 12
A8: # | B8: Income Statement
B9: Sales | C9: =IFERROR('Raw Data Sheet'!E17,0) -> 90791 | D9: =IFERROR('Raw Data Sheet'!F17,0) -> 100472 | E9: =IFERROR('Raw Data Sheet'!G17,0) -> 121641 | F9: =IFERROR('Raw Data Sheet'!H17,0) -> 146767 | G9: =IFERROR('Raw Data Sheet'!I17,0) -> 153670 | H9: =IFERROR('Raw Data Sheet'!J17,0) -> 162990 | I9: =IFERROR('Raw Data Sheet'!K17,0) -> 178650 | J9: =FORECAST(J6,$C$9:$I$9,$C$6:$I$6) -> 196517.57 | K9: =FORECAST(K6,$C$9:$I$9,$C$6:$I$6) -> 211540.5 | L9: =FORECAST(L6,$C$9:$I$9,$C$6:$I$6) -> 226563.43 | M9: =FORECAST(M6,$C$9:$I$9,$C$6:$I$6) -> 241586.36 | N9: =FORECAST(N6,$C$9:$I$9,$C$6:$I$6) -> 256609.29
B10: Sales Growth | C10: - | D10: =D9/C9-1 -> 0.10662951 | E10: =E9/D9-1 -> 0.21069552 | F10: =F9/E9-1 -> 0.20655864 | G10: =G9/F9-1 -> 0.047033734 | H10: =H9/G9-1 -> 0.060649444 | I10: =I9/H9-1 -> 0.096079514 | J10: =J9/I9-1 -> 0.10001439 | K10: =K9/J9-1 -> 0.076445727 | ... N10: =N9/M9-1 -> 0.062184507
B12: COGS | C12: =IFERROR(SUM('Raw Data Sheet'!E20:E22)-1*'Raw Data Sheet'!E19,0) -> 62210 | D12: =IFERROR(SUM('Raw Data Sheet'!F20:F22)-1*'Raw Data Sheet'!F19,0) -> 68490 | E12: =IFERROR(SUM('Raw Data Sheet'!G20:G22)-1*'Raw Data Sheet'!G19,0) -> 84819 | F12: =IFERROR(SUM('Raw Data Sheet'!H20:H22)-1*'Raw Data Sheet'!H19,0) -> 104880 | G12: =IFERROR(SUM('Raw Data Sheet'!I20:I22)-1*'Raw Data Sheet'!I19,0) -> 110030 | H12: =IFERROR(SUM('Raw Data Sheet'!J20:J22)-1*'Raw Data Sheet'!J19,0) -> 116585 | I12: =IFERROR(SUM('Raw Data Sheet'!K20:K22)-1*'Raw Data Sheet'!K19,0) -> 128257 | J12: =FORECAST(J6,$C$12:$I$12,$C$6:$I$6) -> 142116.14 | K12: =FORECAST(K6,$C$12:$I$12,$C$6:$I$6) -> 153528.36 | L12: =FORECAST(L6,$C$12:$I$12,$C$6:$I$6) -> 164940.57 | M12: =FORECAST(M6,$C$12:$I$12,$C$6:$I$6) -> 176352.79 | N12: =FORECAST(N6,$C$12:$I$12,$C$6:$I$6) -> 187765
B13: COGS % of sales | C13: =C12/C9 -> 0.68520007 | D13: =D12/D9 -> 0.68168246 | E13: =E12/E9 -> 0.69728957 | F13: =F12/F9 -> 0.71460206 | G13: =G12/G9 -> 0.71601484 | H13: =H12/H9 -> 0.71528928 | I13: =I12/I9 -> 0.71792331 | J13: =J12/J9 -> 0.7231727 | ... N13: =N12/N9 -> 0.73171553
B15: Gross Profit | C15: =C9-C12 -> 28581 | D15: =D9-D12 -> 31982 | E15: =E9-E12 -> 36822 | F15: =F9-F12 -> 41887 | G15: =G9-G12 -> 43640 | H15: =H9-H12 -> 46405 | I15: =I9-I12 -> 50393 | J15: =J9-J12 -> 54401.429 | ... N15: =N9-N12 -> 68844.286
B16: GP % of sales | C16: =C15/C9 -> 0.31479993 | D16: =D15/D9 -> 0.31831754 | E16: =E15/E9 -> 0.30271043 | F16: =F15/F9 -> 0.28539794 | G16: =G15/G9 -> 0.28398516 | H16: =H15/H9 -> 0.28471072 | I16: =I15/I9 -> 0.28207669 | J16: =J15/J9 -> 0.2768273 | ... N16: =N15/N9 -> 0.26828447
B18: Selling & General Expenses | C18: =IFERROR(SUM('Raw Data Sheet'!E23:E24),0) -> 6314 | D18: =IFERROR(SUM('Raw Data Sheet'!F23:F24),0) -> 4093 | E18: =IFERROR(SUM('Raw Data Sheet'!G23:G24),0) -> 5331 | F18: =IFERROR(SUM('Raw Data Sheet'!H23:H24),0) -> 6757 | G18: =IFERROR(SUM('Raw Data Sheet'!I23:I24),0) -> 7215 | H18: =IFERROR(SUM('Raw Data Sheet'!J23:J24),0) -> 7169 | I18: =IFERROR(SUM('Raw Data Sheet'!K23:K24),0) -> 8113 | J18: =FORECAST(J6,$C$18:$I$18,$C$6:$I$6) -> 8346.4286 | K18: =FORECAST(K6,$C$18:$I$18,$C$6:$I$6) -> 8826.1786 | L18: =FORECAST(L6,$C$18:$I$18,$C$6:$I$6) -> 9305.9286 | M18: =FORECAST(M6,$C$18:$I$18,$C$6:$I$6) -> 9785.6786 | N18: =FORECAST(N6,$C$18:$I$18,$C$6:$I$6) -> 10265.429
B19: S&G Exp % of sales | C19: =C18/C9 -> 0.069544338 | D19: =D18/D9 -> 0.040737718 | E19: =E18/E9 -> 0.043825684 | F19: =F18/F9 -> 0.04603896 | G19: =G18/G9 -> 0.046951259 | H19: =H18/H9 -> 0.043984294 | I19: =I18/I9 -> 0.045412818 | J19: =J18/J9 -> 0.042471666 | ... N19: =N18/N9 -> 0.04000412
B21: EBITDA | C21: =C15-C18 -> 22267 | D21: =D15-D18 -> 27889 | E21: =E15-E18 -> 31491 | F21: =F15-F18 -> 35130 | G21: =G15-G18 -> 36425 | H21: =H15-H18 -> 39236 | I21: =I15-I18 -> 42280 | J21: =J15-J18 -> 46055 | ... N21: =N15-N18 -> 58578.857
B22: EBITDA % OF SALES | C22: =C21/C9 -> 0.24525559 | D22: =D21/D9 -> 0.27757982 | E22: =E21/E9 -> 0.25888475 | F22: =F21/F9 -> 0.23935898 | G22: =G21/G9 -> 0.2370339 | H22: =H21/H9 -> 0.24072642 | I22: =I21/I9 -> 0.23666387 | J22: =J21/J9 -> 0.23435563 | ... N22: =N21/N9 -> 0.22828035
B24: Interest | C24: =IFERROR('Raw Data Sheet'!E27,0) -> 170 | D24: =IFERROR('Raw Data Sheet'!F27,0) -> 195 | E24: =IFERROR('Raw Data Sheet'!G27,0) -> 200 | F24: =IFERROR('Raw Data Sheet'!H27,0) -> 284 | G24: =IFERROR('Raw Data Sheet'!I27,0) -> 470 | H24: =IFERROR('Raw Data Sheet'!J27,0) -> 416 | I24: =IFERROR('Raw Data Sheet'!K27,0) -> 416 | J24: =FORECAST(J6,$C$24:$I$24,$C$6:$I$6) -> 514.42857 | K24: =FORECAST(K6,$C$24:$I$24,$C$6:$I$6) -> 566.21429 | L24: =FORECAST(L6,$C$24:$I$24,$C$6:$I$6) -> 618 | M24: =FORECAST(M6,$C$24:$I$24,$C$6:$I$6) -> 669.78571 | N24: =FORECAST(N6,$C$24:$I$24,$C$6:$I$6) -> 721.57143
B25: Interest % of sales | C25: =C24/C9 -> 0.0018724323 | D25: =D24/D9 -> 0.0019408392 | E25: =E24/E9 -> 0.0016441825 | F25: =F24/F9 -> 0.0019350399 | G25: =G24/G9 -> 0.003058502 | H25: =H24/H9 -> 0.0025523038 | I25: =I24/I9 -> 0.0023285754 | J25: =J24/J9 -> 0.002617723 | ... N25: =N24/N9 -> 0.0028119459
B27: Depreciation | C27: =IFERROR('Raw Data Sheet'!E26,0) -> 2893 | D27: =IFERROR('Raw Data Sheet'!F26,0) -> 3267 | E27: =IFERROR('Raw Data Sheet'!G26,0) -> 3476 | F27: =IFERROR('Raw Data Sheet'!H26,0) -> 4225 | G27: =IFERROR('Raw Data Sheet'!I26,0) -> 4678 | H27: =IFERROR('Raw Data Sheet'!J26,0) -> 4812 | I27: =IFERROR('Raw Data Sheet'!K26,0) -> 4902 | J27: =FORECAST(J6,$C$27:$I$27,$C$6:$I$6) -> 5510.2857 | K27: =FORECAST(K6,$C$27:$I$27,$C$6:$I$6) -> 5878.8214 | L27: =FORECAST(L6,$C$27:$I$27,$C$6:$I$6) -> 6247.3571 | M27: =FORECAST(M6,$C$27:$I$27,$C$6:$I$6) -> 6615.8929 | N27: =FORECAST(N6,$C$27:$I$27,$C$6:$I$6) -> 6984.4286
B28: Dep % of sales | C28: =C27/C9 -> 0.031864392 | D28: =D27/D9 -> 0.032516522 | E28: =E27/E9 -> 0.028575891 | F28: =F27/F9 -> 0.028787125 | G28: =G27/G9 -> 0.030441856 | H28: =H27/H9 -> 0.029523284 | I28: =I27/I9 -> 0.027439127 | J28: =J27/J9 -> 0.028039659 | ... N28: =N27/N9 -> 0.027218144
B30: Earnings before Tax | C30: =C21-SUM(C24+C27) -> 19204 | D30: =D21-SUM(D24+D27) -> 24427 | E30: =E21-SUM(E24+E27) -> 27815 | F30: =F21-SUM(F24+F27) -> 30621 | G30: =G21-SUM(G24+G27) -> 31277 | H30: =H21-SUM(H24+H27) -> 34008 | I30: =I21-SUM(I24+I27) -> 36962 | J30: =J21-SUM(J24+J27) -> 40030.286 | ... N30: =N21-SUM(N24+N27) -> 50872.857
B31: EBT % of sales | C31: =C30/C9 -> 0.21151876 | D31: =D30/D9 -> 0.24312246 | E31: =E30/E9 -> 0.22866468 | F31: =F30/F9 -> 0.20863682 | G31: =G30/G9 -> 0.20353355 | H31: =H30/H9 -> 0.20865084 | I31: =I30/I9 -> 0.20689617 | J31: =J30/J9 -> 0.20369825 | ... N31: =N30/N9 -> 0.19825026
B33: Tax | C33: =IFERROR('Raw Data Sheet'!E29,0) -> 5368 | D33: =IFERROR('Raw Data Sheet'!F29,0) -> 7205 | E33: =IFERROR('Raw Data Sheet'!G29,0) -> 7964 | F33: =IFERROR('Raw Data Sheet'!H29,0) -> 9214 | G33: =IFERROR('Raw Data Sheet'!I29,0) -> 9740 | H33: =IFERROR('Raw Data Sheet'!J29,0) -> 10858 | I33: =IFERROR('Raw Data Sheet'!K29,0) -> 10521 | J33: =FORECAST(J6,$C$33:$I$33,$C$6:$I$6) -> 12201.571 | K33: =FORECAST(K6,$C$33:$I$33,$C$6:$I$6) -> 13078.036 | L33: =FORECAST(L6,$C$33:$I$33,$C$6:$I$6) -> 13954.5 | M33: =FORECAST(M6,$C$33:$I$33,$C$6:$I$6) -> 14830.964 | N33: =FORECAST(N6,$C$33:$I$33,$C$6:$I$6) -> 15707.429
B34: Effective tax rate | C34: =C33/C30 -> 0.2795251 | D34: =D33/D30 -> 0.29496049 | E34: =E33/E30 -> 0.28632033 | F34: =F33/F30 -> 0.30090461 | G34: =G33/G30 -> 0.31141094 | H34: =H33/H30 -> 0.31927782 | I34: =I33/I30 -> 0.28464369 | J34: =J33/J30 -> 0.3048085 | ... N34: =N33/N30 -> 0.30875853
B36: Net profit | C36: =C30-C33 -> 13836 | D36: =D30-D33 -> 17222 | E36: =E30-E33 -> 19851 | F36: =F30-F33 -> 21407 | G36: =G30-G33 -> 21537 | H36: =H30-H33 -> 23150 | I36: =I30-I33 -> 26441 | J36: =J30-J33 -> 27828.714 | ... N36: =N30-N33 -> 35165.429
B37: Net Margin | C37: =C36/C9 -> 0.15239396 | D37: =D36/D9 -> 0.17141094 | E37: =E36/E9 -> 0.16319333 | F37: =F36/F9 -> 0.14585704 | G37: =G36/G9 -> 0.14015097 | H37: =H36/H9 -> 0.14203325 | I37: =I36/I9 -> 0.14800448 | J37: =J36/J9 -> 0.14160929 | ... N37: =N36/N9 -> 0.1370388
B39: No. of Equity Shares | C39: =IFERROR('Raw Data Sheet'!E93,0) -> 425.9 | D39: =IFERROR('Raw Data Sheet'!F93,0) -> 426.07 | E39: =IFERROR('Raw Data Sheet'!G93,0) -> 420.67 | F39: =IFERROR('Raw Data Sheet'!H93,0) -> 414.86 | G39: =IFERROR('Raw Data Sheet'!I93,0) -> 415.09 | H39: =IFERROR('Raw Data Sheet'!J93,0) -> 415.33 | I39: =IFERROR('Raw Data Sheet'!K93,0) -> 405.56 | J39: =FORECAST(J6,$C$39:$I$39,$C$6:$I$6) -> 405.05714 | K39: =FORECAST(K6,$C$39:$I$39,$C$6:$I$6) -> 401.91143 | L39: =FORECAST(L6,$C$39:$I$39,$C$6:$I$6) -> 398.76571 | M39: =FORECAST(M6,$C$39:$I$39,$C$6:$I$6) -> 395.62 | N39: =FORECAST(N6,$C$39:$I$39,$C$6:$I$6) -> 392.47429
B41: EPS | C41: =IFERROR(C36/C39,0) -> 32.486499 | D41: =IFERROR(D36/D39,0) -> 40.420588 | E41: =IFERROR(E36/E39,0) -> 47.189008 | F41: =IFERROR(F36/F39,0) -> 51.60054 | G41: =IFERROR(G36/G39,0) -> 51.885133 | H41: =IFERROR(H36/H39,0) -> 55.73881 | I41: =IFERROR(I36/I39,0) -> 65.196272 | J41: =IFERROR(J36/J39,0) -> 68.703181 | ... N41: =IFERROR(N36/N39,0) -> 89.599319
B42: EPS growth | D42: =D41/C41-1 -> 0.24422727 | E42: =E41/D41-1 -> 0.16744981 | F42: =F41/E41-1 -> 0.093486431 | G42: =G41/F41-1 -> 0.0055153183 | H42: =H41/G41-1 -> 0.074273236 | I42: =I41/H41-1 -> 0.16967463 | J42: =J41/I41-1 -> 0.05379003 | K42: =K41/J41-1 -> 0.07425232 | ... N42: =N41/M41-1 -> 0.063484941
B44: Dividend per share | C44: =IFERROR('Raw Data Sheet'!E31/C39,0) -> 17.438366 | D44: =IFERROR('Raw Data Sheet'!F31/D39,0) -> 26.91952 | E44: =IFERROR('Raw Data Sheet'!G31/E39,0) -> 30.92115 | F44: =IFERROR('Raw Data Sheet'!H31/F39,0) -> 33.913127 | G44: =IFERROR('Raw Data Sheet'!I31/G39,0) -> 45.901371 | H44: =IFERROR('Raw Data Sheet'!J31/H39,0) -> 42.924422 | I44: =IFERROR('Raw Data Sheet'!K31/I39,0) -> 47.91005 | J44: =FORECAST(J6,$C$44:$I$44,$C$6:$I$6) -> 54.904726 | K44: =FORECAST(K6,$C$44:$I$44,$C$6:$I$6) -> 59.847765 | L44: =FORECAST(L6,$C$44:$I$44,$C$6:$I$6) -> 64.790803 | M44: =FORECAST(M6,$C$44:$I$44,$C$6:$I$6) -> 69.733842 | N44: =FORECAST(N6,$C$44:$I$44,$C$6:$I$6) -> 74.67688
B45: D/D Payout Ratio | C45: =IFERROR(C44/C41,0) -> 0.53678809 | D45: =IFERROR(D44/D41,0) -> 0.66598537 | E45: =IFERROR(E44/E41,0) -> 0.6552617 | F45: =IFERROR(F44/F41,0) -> 0.65722427 | G45: =IFERROR(G44/G41,0) -> 0.88467289 | H45: =IFERROR(H44/H41,0) -> 0.77009935 | I45: =IFERROR(I44/I41,0) -> 0.73485874 | J45: =IFERROR(J44/J41,0) -> 0.79915843 | ... N45: =IFERROR(N44/N41,0) -> 0.83345366
B47: Retained Earnings | C47: =IFERROR(IF(C41>C44,1-C45,0),0) -> 0.46321191 | D47: =IFERROR(IF(D41>D44,1-D45,0),0) -> 0.33401463 | E47: =IFERROR(IF(E41>E44,1-E45,0),0) -> 0.3447383 | F47: =IFERROR(IF(F41>F44,1-F45,0),0) -> 0.34277573 | G47: =IFERROR(IF(G41>G44,1-G45,0),0) -> 0.11532711 | H47: =IFERROR(IF(H41>H44,1-H45,0),0) -> 0.22990065 | I47: =IFERROR(IF(I41>I44,1-I45,0),0) -> 0.26514126 | J47: =IFERROR(IF(J41>J44,1-J45,0),0) -> 0.20084157 | ... N47: =IFERROR(IF(N41>N44,1-N45,0),0) -> 0.16654634
B48: EBIT | C48: =IFERROR(C21-C27,0) -> 19374 | D48: =IFERROR(D21-D27,0) -> 24622 | E48: =IFERROR(E21-E27,0) -> 28015 | F48: =IFERROR(F21-F27,0) -> 30905 | G48: =IFERROR(G21-G27,0) -> 31747 | H48: =IFERROR(H21-H27,0) -> 34424 | I48: =IFERROR(I21-I27,0) -> 37378 | J48: =IFERROR(J21-J27,0) -> 40544.714 | ... N48: =IFERROR(N21-N27,0) -> 51594.429
B49: EBIT Margin | C49: =C48/C9 -> 0.2133912 | D49: =D48/D9 -> 0.2450633 | E49: =E48/E9 -> 0.23030886 | F49: =F48/F9 -> 0.21057186 | G49: =G48/G9 -> 0.20659205 | H49: =H48/H9 -> 0.21120314 | I49: =I48/I9 -> 0.20922474 | J49: =J48/J9 -> 0.20631597 | ... N49: =N48/N9 -> 0.2010622
A50: # | B50: Balance Sheet
B52: Equity Share Capital | C52: =IFERROR('Raw Data Sheet'!E57,0) -> 2122 | D52: =IFERROR('Raw Data Sheet'!F57,0) -> 2124 | E52: =IFERROR('Raw Data Sheet'!G57,0) -> 2098 | F52: =IFERROR('Raw Data Sheet'!H57,0) -> 2069 | G52: =IFERROR('Raw Data Sheet'!I57,0) -> 2071 | H52: =IFERROR('Raw Data Sheet'!J57,0) -> 2073 | I52: =IFERROR('Raw Data Sheet'!K57,0) -> 2024 | J52: =FORECAST(J6,$C$52:$I$52,$C$6:$I$6) -> 2022.5714 | K52: =FORECAST(K6,$C$52:$I$52,$C$6:$I$6) -> 2007.4643 | L52: =FORECAST(L6,$C$52:$I$52,$C$6:$I$6) -> 1992.3571 | M52: =FORECAST(M6,$C$52:$I$52,$C$6:$I$6) -> 1977.25 | N52: =FORECAST(N6,$C$52:$I$52,$C$6:$I$6) -> 1962.1429
B53: Reserves | C53: =IFERROR('Raw Data Sheet'!E58,0) -> 63328 | D53: =IFERROR('Raw Data Sheet'!F58,0) -> 74227 | E53: =IFERROR('Raw Data Sheet'!G58,0) -> 73252 | F53: =IFERROR('Raw Data Sheet'!H58,0) -> 73338 | G53: =IFERROR('Raw Data Sheet'!I58,0) -> 86045 | H53: =IFERROR('Raw Data Sheet'!J58,0) -> 93745 | I53: =IFERROR('Raw Data Sheet'!K58,0) -> 90828 | J53: =FORECAST($J$6,C53:I53,$C$6:$I$6) -> 98441.714 | K53: =FORECAST($J$6,D53:J53,$C$6:$I$6) -> 102582.84 | L53: =FORECAST($J$6,E53:K53,$C$6:$I$6) -> 108745.07 | M53: =FORECAST($J$6,F53:L53,$C$6:$I$6) -> 113959.89 | N53: =FORECAST($J$6,G53:M53,$C$6:$I$6) -> 117121.02
B54: Borrowings | C54: =IFERROR('Raw Data Sheet'!E59,0) -> 4633 | D54: =IFERROR('Raw Data Sheet'!F59,0) -> 5325 | E54: =IFERROR('Raw Data Sheet'!G59,0) -> 5474 | F54: =IFERROR('Raw Data Sheet'!H59,0) -> 8299 | G54: =IFERROR('Raw Data Sheet'!I59,0) -> 8359 | H54: =IFERROR('Raw Data Sheet'!J59,0) -> 8227 | I54: =IFERROR('Raw Data Sheet'!K59,0) -> 9176 | J54: =FORECAST($J$6,C54:I54,$C$6:$I$6) -> 10258.714 | K54: =FORECAST($J$6,D54:J54,$C$6:$I$6) -> 11035.98 | L54: =FORECAST($J$6,E54:K54,$C$6:$I$6) -> 11750.294 | M54: =FORECAST($J$6,F54:L54,$C$6:$I$6) -> 12120.792 | N54: =FORECAST($J$6,G54:M54,$C$6:$I$6) -> 13017.104
B55: Other Liabilities | C55: =IFERROR('Raw Data Sheet'!E60,0) -> 21717 | D55: =IFERROR('Raw Data Sheet'!F60,0) -> 25835 | E55: =IFERROR('Raw Data Sheet'!G60,0) -> 35905 | F55: =IFERROR('Raw Data Sheet'!H60,0) -> 40890 | G55: =IFERROR('Raw Data Sheet'!I60,0) -> 39545 | H55: =IFERROR('Raw Data Sheet'!J60,0) -> 43750 | I55: =IFERROR('Raw Data Sheet'!K60,0) -> 52260 | J55: =FORECAST($J$6,C55:I55,$C$6:$I$6) -> 55857.286 | K55: =FORECAST($J$6,D55:J55,$C$6:$I$6) -> 59954.163 | L55: =FORECAST($J$6,E55:K55,$C$6:$I$6) -> 63279.787 | M55: =FORECAST($J$6,F55:L55,$C$6:$I$6) -> 67947.316 | N55: =FORECAST($J$6,G55:M55,$C$6:$I$6) -> 73507.748
B56: Total Liabilities | C56: =SUM(C52:C55) -> 91800 | D56: =SUM(D52:D55) -> 107511 | E56: =SUM(E52:E55) -> 116729 | F56: =SUM(F52:F55) -> 124596 | G56: =SUM(G52:G55) -> 136020 | H56: =SUM(H52:H55) -> 147795 | I56: =SUM(I52:I55) -> 154288 | J56: =SUM(J52:J55) -> 166580.29 | ... N56: =SUM(N52:N55) -> 205608.02
B58: Fixed Assets Net Block | C58: =IFERROR('Raw Data Sheet'!E62,0) -> 23789 | D58: =IFERROR('Raw Data Sheet'!F62,0) -> 25505 | E58: =IFERROR('Raw Data Sheet'!G62,0) -> 25800 | F58: =IFERROR('Raw Data Sheet'!H62,0) -> 29225 | G58: =IFERROR('Raw Data Sheet'!I62,0) -> 27622 | H58: =IFERROR('Raw Data Sheet'!J62,0) -> 30961 | I58: =IFERROR('Raw Data Sheet'!K62,0) -> 33770 | J58: =FORECAST($J$6,C58:I58,$C$6:$I$6) -> 34192.714 | K58: =FORECAST($J$6,D58:J58,$C$6:$I$6) -> 35830.694 | L58: =FORECAST($J$6,E58:K58,$C$6:$I$6) -> 37653.845 | M58: =FORECAST($J$6,F58:L58,$C$6:$I$6) -> 39170.127 | N58: =FORECAST($J$6,G58:M58,$C$6:$I$6) -> 41327.307
...

Sheet Ratio Analysis
B2: ="Ratio Analysis - "& 'Raw Data Sheet'!B1 -> Ratio Analysis - INFOSYS LTD
B3: Years | C3: ='Raw Data Sheet'!E16 -> 43921 | D3: ='Raw Data Sheet'!F16 -> 44286 | E3: ='Raw Data Sheet'!G16 -> 44651 | F3: ='Raw Data Sheet'!H16 -> 45016 | G3: ='Raw Data Sheet'!I16 -> 45382 | H3: ='Raw Data Sheet'!J16 -> 45747 | I3: ='Raw Data Sheet'!K16 -> 46112 | J3: Trend | K3: Mean | L3: Median
B5: SalesGrowth | D5: =IFERROR((' Forecasted FS>'!D9/' Forecasted FS>'!C9)-1,0) -> 0.10662951 | E5: =IFERROR((' Forecasted FS>'!E9/' Forecasted FS>'!D9)-1,0) -> 0.21069552 | F5: =IFERROR((' Forecasted FS>'!F9/' Forecasted FS>'!E9)-1,0) -> 0.20655864 | G5: =IFERROR((' Forecasted FS>'!G9/' Forecasted FS>'!F9)-1,0) -> 0.047033734 | H5: =IFERROR((' Forecasted FS>'!H9/' Forecasted FS>'!G9)-1,0) -> 0.060649444 | I5: =IFERROR((' Forecasted FS>'!I9/' Forecasted FS>'!H9)-1,0) -> 0.096079514 | K5: =IFERROR(AVERAGE(D5:I5),0) -> 0.12127439 | L5: =IFERROR(MEDIAN(C5:I5),0) -> 0.10135451
B6: EBITDA Growth | D6: =IFERROR((' Forecasted FS>'!D21/' Forecasted FS>'!C21)-1,0) -> 0.25248125 | E6: =IFERROR((' Forecasted FS>'!E21/' Forecasted FS>'!D21)-1,0) -> 0.12915486 | F6: =IFERROR((' Forecasted FS>'!F21/' Forecasted FS>'!E21)-1,0) -> 0.11555683 | G6: =IFERROR((' Forecasted FS>'!G21/' Forecasted FS>'!F21)-1,0) -> 0.03686308 | H6: =IFERROR((' Forecasted FS>'!H21/' Forecasted FS>'!G21)-1,0) -> 0.077172272 | I6: =IFERROR((' Forecasted FS>'!I21/' Forecasted FS>'!H21)-1,0) -> 0.077581813 | K6: =IFERROR(AVERAGE(D6:I6),0) -> 0.11480168 | L6: =IFERROR(MEDIAN(C6:I6),0) -> 0.096569319
B7: EBIT Growth | D7: =IFERROR((' Forecasted FS>'!D48/' Forecasted FS>'!C48)-1,0) -> 0.2708785 | E7: =IFERROR((' Forecasted FS>'!E48/' Forecasted FS>'!D48)-1,0) -> 0.13780359 | F7: =IFERROR((' Forecasted FS>'!F48/' Forecasted FS>'!E48)-1,0) -> 0.10315902 | G7: =IFERROR((' Forecasted FS>'!G48/' Forecasted FS>'!F48)-1,0) -> 0.027244782 | H7: =IFERROR((' Forecasted FS>'!H48/' Forecasted FS>'!G48)-1,0) -> 0.084322928 | I7: =IFERROR((' Forecasted FS>'!I48/' Forecasted FS>'!H48)-1,0) -> 0.085812224 | K7: =IFERROR(AVERAGE(D7:I7),0) -> 0.11820351 | L7: =IFERROR(MEDIAN(C7:I7),0) -> 0.094485623
B8: Net Profit Growth | D8: =IFERROR((' Forecasted FS>'!D30/' Forecasted FS>'!C30)-1,0) -> 0.27197459 | E8: =IFERROR((' Forecasted FS>'!E30/' Forecasted FS>'!D30)-1,0) -> 0.13869898 | F8: =IFERROR((' Forecasted FS>'!F30/' Forecasted FS>'!E30)-1,0) -> 0.10088082 | G8: =IFERROR((' Forecasted FS>'!G30/' Forecasted FS>'!F30)-1,0) -> 0.021423206 | H8: =IFERROR((' Forecasted FS>'!H30/' Forecasted FS>'!G30)-1,0) -> 0.087316558 | I8: =IFERROR((' Forecasted FS>'!I30/' Forecasted FS>'!H30)-1,0) -> 0.086861915 | K8: =IFERROR(AVERAGE(D8:I8),0) -> 0.11785934 | L8: =IFERROR(MEDIAN(C8:I8),0) -> 0.094098689
B9: Dividend Growth | D9: =IFERROR((' Forecasted FS>'!D44/' Forecasted FS>'!C44)-1,0) -> 0.54369512 | E9: =IFERROR((' Forecasted FS>'!E44/' Forecasted FS>'!D44)-1,0) -> 0.14865158 | F9: =IFERROR((' Forecasted FS>'!F44/' Forecasted FS>'!E44)-1,0) -> 0.096761529 | G9: =IFERROR((' Forecasted FS>'!G44/' Forecasted FS>'!F44)-1,0) -> 0.35349861 | H9: =IFERROR((' Forecasted FS>'!H44/' Forecasted FS>'!G44)-1,0) -> -0.064855345 | I9: =IFERROR((' Forecasted FS>'!I44/' Forecasted FS>'!H44)-1,0) -> 0.116149 | K9: =IFERROR(AVERAGE(D9:I9),0) -> 0.19898342 | L9: =IFERROR(MEDIAN(C9:I9),0) -> 0.13240029
B11: Gross Margin | C11: =IFERROR(' Forecasted FS>'!C16,0) -> 0.31479993 | D11: =IFERROR(' Forecasted FS>'!D16,0) -> 0.31831754 | E11: =IFERROR(' Forecasted FS>'!E16,0) -> 0.30271043 | F11: =IFERROR(' Forecasted FS>'!F16,0) -> 0.28539794 | G11: =IFERROR(' Forecasted FS>'!G16,0) -> 0.28398516 | H11: =IFERROR(' Forecasted FS>'!H16,0) -> 0.28471072 | I11: =IFERROR(' Forecasted FS>'!I16,0) -> 0.28207669 | K11: =IFERROR(AVERAGE(C11:I11),0) -> 0.29599977 | L11: =IFERROR(MEDIAN(C11:I11),0) -> 0.28539794
B12: EBITDA Margin | C12: =IFERROR(' Forecasted FS>'!C22,0) -> 0.24525559 | D12: =IFERROR(' Forecasted FS>'!D22,0) -> 0.27757982 | E12: =IFERROR(' Forecasted FS>'!E22,0) -> 0.25888475 | F12: =IFERROR(' Forecasted FS>'!F22,0) -> 0.23935898 | G12: =IFERROR(' Forecasted FS>'!G22,0) -> 0.2370339 | H12: =IFERROR(' Forecasted FS>'!H22,0) -> 0.24072642 | I12: =IFERROR(' Forecasted FS>'!I22,0) -> 0.23666387 | K12: =IFERROR(AVERAGE(C12:I12),0) -> 0.24792905 | L12: =IFERROR(MEDIAN(C12:I12),0) -> 0.24072642
B13: EBIT Margin | C13: =IFERROR(' Forecasted FS>'!C49,0) -> 0.2133912 | D13: =IFERROR(' Forecasted FS>'!D49,0) -> 0.2450633 | E13: =IFERROR(' Forecasted FS>'!E49,0) -> 0.23030886 | F13: =IFERROR(' Forecasted FS>'!F49,0) -> 0.21057186 | G13: =IFERROR(' Forecasted FS>'!G49,0) -> 0.20659205 | H13: =IFERROR(' Forecasted FS>'!H49,0) -> 0.21120314 | I13: =IFERROR(' Forecasted FS>'!I49,0) -> 0.20922474 | K13: =IFERROR(AVERAGE(C13:I13),0) -> 0.21805074 | L13: =IFERROR(MEDIAN(C13:I13),0) -> 0.21120314
B14: EBT Margin | C14: =IFERROR(' Forecasted FS>'!C31,0) -> 0.21151876 | D14: =IFERROR(' Forecasted FS>'!D31,0) -> 0.24312246 | E14: =IFERROR(' Forecasted FS>'!E31,0) -> 0.22866468 | F14: =IFERROR(' Forecasted FS>'!F31,0) -> 0.20863682 | G14: =IFERROR(' Forecasted FS>'!G31,0) -> 0.20353355 | H14: =IFERROR(' Forecasted FS>'!H31,0) -> 0.20865084 | I14: =IFERROR(' Forecasted FS>'!I31,0) -> 0.20689617 | K14: =IFERROR(AVERAGE(C14:I14),0) -> 0.21586047 | L14: =IFERROR(MEDIAN(C14:I14),0) -> 0.20865084
B15: Net Profit Margin | C15: =IFERROR(' Forecasted FS>'!C37,0) -> 0.15239396 | D15: =IFERROR(' Forecasted FS>'!D37,0) -> 0.17141094 | E15: =IFERROR(' Forecasted FS>'!E37,0) -> 0.16319333 | F15: =IFERROR(' Forecasted FS>'!F37,0) -> 0.14585704 | G15: =IFERROR(' Forecasted FS>'!G37,0) -> 0.14015097 | H15: =IFERROR(' Forecasted FS>'!H37,0) -> 0.14203325 | I15: =IFERROR(' Forecasted FS>'!I37,0) -> 0.14800448 | K15: =IFERROR(AVERAGE(C15:I15),0) -> 0.15186342 | L15: =IFERROR(MEDIAN(C15:I15),0) -> 0.14800448
B17: SalesExpenses%Sales | C17: =IFERROR(' Forecasted FS>'!C19,0) -> 0.069544338 | D17: =IFERROR(' Forecasted FS>'!D19,0) -> 0.040737718 | E17: =IFERROR(' Forecasted FS>'!E19,0) -> 0.043825684 | F17: =IFERROR(' Forecasted FS>'!F19,0) -> 0.04603896 | G17: =IFERROR(' Forecasted FS>'!G19,0) -> 0.046951259 | H17: =IFERROR(' Forecasted FS>'!H19,0) -> 0.043984294 | I17: =IFERROR(' Forecasted FS>'!I19,0) -> 0.045412818 | K17: =IFERROR(AVERAGE(C17:I17),0) -> 0.048070724 | L17: =IFERROR(MEDIAN(C17:I17),0) -> 0.045412818
B18: Depreciation%Sales | C18: =IFERROR(' Forecasted FS>'!C28,0) -> 0.031864392 | D18: =IFERROR(' Forecasted FS>'!D28,0) -> 0.032516522 | E18: =IFERROR(' Forecasted FS>'!E28,0) -> 0.028575891 | F18: =IFERROR(' Forecasted FS>'!F28,0) -> 0.028787125 | G18: =IFERROR(' Forecasted FS>'!G28,0) -> 0.030441856 | H18: =IFERROR(' Forecasted FS>'!H28,0) -> 0.029523284 | I18: =IFERROR(' Forecasted FS>'!I28,0) -> 0.027439127 | K18: =IFERROR(AVERAGE(C18:I18),0) -> 0.029878314 | L18: =IFERROR(MEDIAN(C18:I18),0) -> 0.029523284
B19: OperatingIncome%Sales | C19: =IFERROR(C13,0) -> 0.2133912 | D19: =IFERROR(D13,0) -> 0.2450633 | E19: =IFERROR(E13,0) -> 0.23030886 | F19: =IFERROR(F13,0) -> 0.21057186 | G19: =IFERROR(G13,0) -> 0.20659205 | H19: =IFERROR(H13,0) -> 0.21120314 | I19: =IFERROR(I13,0) -> 0.20922474 | K19: =IFERROR(AVERAGE(C19:I19),0) -> 0.21805074 | L19: =IFERROR(MEDIAN(C19:I19),0) -> 0.21120314
B21: Return on Capital Employed | C21: =(' Forecasted FS>'!C21-' Forecasted FS>'!C27)/(SUM(' Forecasted FS>'!C52:C54)) -> 0.27644365 | D21: =(' Forecasted FS>'!D21-' Forecasted FS>'!D27)/(SUM(' Forecasted FS>'!D52:D54)) -> 0.30145943 | E21: =(' Forecasted FS>'!E21-' Forecasted FS>'!E27)/(SUM(' Forecasted FS>'!E52:E54)) -> 0.34661734 | F21: =(' Forecasted FS>'!F21-' Forecasted FS>'!F27)/(SUM(' Forecasted FS>'!F52:F54)) -> 0.3692089 | G21: =(' Forecasted FS>'!G21-' Forecasted FS>'!G27)/(SUM(' Forecasted FS>'!G52:G54)) -> 0.32906971 | H21: =(' Forecasted FS>'!H21-' Forecasted FS>'!H27)/(SUM(' Forecasted FS>'!H52:H54)) -> 0.33085684 | I21: =(' Forecasted FS>'!I21-' Forecasted FS>'!I27)/(SUM(' Forecasted FS>'!I52:I54)) -> 0.36635041 | K21: =IFERROR(AVERAGE(C21:I21),0) -> 0.33142947 | L21: =IFERROR(MEDIAN(C21:I21),0) -> 0.33085684
B22: Retained Earnings% | C22: =IFERROR(' Forecasted FS>'!C47,0) -> 0.46321191 | D22: =IFERROR(' Forecasted FS>'!D47,0) -> 0.33401463 | E22: =IFERROR(' Forecasted FS>'!E47,0) -> 0.3447383 | F22: =IFERROR(' Forecasted FS>'!F47,0) -> 0.34277573 | G22: =IFERROR(' Forecasted FS>'!G47,0) -> 0.11532711 | H22: =IFERROR(' Forecasted FS>'!H47,0) -> 0.22990065 | I22: =IFERROR(' Forecasted FS>'!I47,0) -> 0.26514126 | K22: =IFERROR(AVERAGE(C22:I22),0) -> 0.29930137 | L22: =IFERROR(MEDIAN(C22:I22),0) -> 0.33401463
B23: Return on Equity% | C23: =IFERROR(' Forecasted FS>'!C36/(SUM(' Forecasted FS>'!C52:C53)),0) -> 0.21139801 | D23: =IFERROR(' Forecasted FS>'!D36/(SUM(' Forecasted FS>'!D52:D53)),0) -> 0.22556352 | E23: =IFERROR(' Forecasted FS>'!E36/(SUM(' Forecasted FS>'!E52:E53)),0) -> 0.26345056 | F23: =IFERROR(' Forecasted FS>'!F36/(SUM(' Forecasted FS>'!F52:F53)),0) -> 0.28388611 | G23: =IFERROR(' Forecasted FS>'!G36/(SUM(' Forecasted FS>'!G52:G53)),0) -> 0.24441645 | H23: =IFERROR(' Forecasted FS>'!H36/(SUM(' Forecasted FS>'!H52:H53)),0) -> 0.24160387 | I23: =IFERROR(' Forecasted FS>'!I36/(SUM(' Forecasted FS>'!I52:I53)),0) -> 0.284765 | K23: =IFERROR(AVERAGE(C23:I23),0) -> 0.25072622 | L23: =IFERROR(MEDIAN(C23:I23),0) -> 0.24441645
B24: Self Sustained Growth Rate | C24: =IFERROR(C22*C23,0) -> 0.097922078 | D24: =IFERROR(D22*D23,0) -> 0.075341515 | E24: =IFERROR(E22*E23,0) -> 0.0908215 | F24: =IFERROR(F22*F23,0) -> 0.097309268 | G24: =IFERROR(G22*G23,0) -> 0.028187843 | H24: =IFERROR(H22*H23,0) -> 0.055544887 | I24: =IFERROR(I22*I23,0) -> 0.075502951 | K24: =IFERROR(AVERAGE(C24:I24),0) -> 0.07437572 | L24: =IFERROR(MEDIAN(C24:I24),0) -> 0.075502951
B25: Interest Coverage Ratio | C25: =' Forecasted FS>'!C21/' Forecasted FS>'!C24 -> 130.98235 | D25: =' Forecasted FS>'!D21/' Forecasted FS>'!D24 -> 143.02051 | E25: =' Forecasted FS>'!E21/' Forecasted FS>'!E24 -> 157.455 | F25: =' Forecasted FS>'!F21/' Forecasted FS>'!F24 -> 123.69718 | G25: =' Forecasted FS>'!G21/' Forecasted FS>'!G24 -> 77.5 | H25: =' Forecasted FS>'!H21/' Forecasted FS>'!H24 -> 94.317308 | I25: =' Forecasted FS>'!I21/' Forecasted FS>'!I24 -> 101.63462 | K25: =IFERROR(AVERAGE(C25:I25),0) -> 118.37242 | L25: =IFERROR(MEDIAN(C25:I25),0) -> 123.69718
B27: Debtor Turnover Ratio | C27: =' Forecasted FS>'!C9/' Forecasted FS>'!C64 -> 4.9110726 | D27: =' Forecasted FS>'!D9/' Forecasted FS>'!D64 -> 5.207422 | E27: =' Forecasted FS>'!E9/' Forecasted FS>'!E64 -> 5.3591065 | F27: =' Forecasted FS>'!F9/' Forecasted FS>'!F64 -> 5.7727738 | G27: =' Forecasted FS>'!G9/' Forecasted FS>'!G64 -> 5.0895903 | H27: =' Forecasted FS>'!H9/' Forecasted FS>'!H64 -> 5.2310803 | I27: =' Forecasted FS>'!I9/' Forecasted FS>'!I64 -> 5.0703866 | K27: =IFERROR(AVERAGE(C27:I27),0) -> 5.2344903 | L27: =IFERROR(MEDIAN(C27:I27),0) -> 5.207422
B28: Creditor Turnover Ratio | C28: =' Forecasted FS>'!C9/' Forecasted FS>'!C55 -> 4.1806419 | D28: =' Forecasted FS>'!D9/' Forecasted FS>'!D55 -> 3.8889878 | E28: =' Forecasted FS>'!E9/' Forecasted FS>'!E55 -> 3.3878568 | F28: =' Forecasted FS>'!F9/' Forecasted FS>'!F55 -> 3.5893128 | G28: =' Forecasted FS>'!G9/' Forecasted FS>'!G55 -> 3.8859527 | H28: =' Forecasted FS>'!H9/' Forecasted FS>'!H55 -> 3.7254857 | I28: =' Forecasted FS>'!I9/' Forecasted FS>'!I55 -> 3.4184845 | K28: =IFERROR(AVERAGE(C28:I28),0) -> 3.725246 | L28: =IFERROR(MEDIAN(C28:I28),0) -> 3.7254857
B29: Inventory Turnover | C29: =IFERROR(' Forecasted FS>'!C9/' Forecasted FS>'!C65,0) -> 0 | D29: =IFERROR(' Forecasted FS>'!D9/' Forecasted FS>'!D65,0) -> 0 | E29: =IFERROR(' Forecasted FS>'!E9/' Forecasted FS>'!E65,0) -> 0 | F29: =IFERROR(' Forecasted FS>'!F9/' Forecasted FS>'!F65,0) -> 0 | G29: =IFERROR(' Forecasted FS>'!G9/' Forecasted FS>'!G65,0) -> 0 | H29: =IFERROR(' Forecasted FS>'!H9/' Forecasted FS>'!H65,0) -> 0 | I29: =IFERROR(' Forecasted FS>'!I9/' Forecasted FS>'!I65,0) -> 0 | K29: =IFERROR(AVERAGE(C29:I29),0) -> 0 | L29: =IFERROR(MEDIAN(C29:I29),0) -> 0
B30: Fixed Asset Turnover | C30: =' Forecasted FS>'!C9/' Forecasted FS>'!C58 -> 3.8165118 | D30: =' Forecasted FS>'!D9/' Forecasted FS>'!D58 -> 3.939306 | E30: =' Forecasted FS>'!E9/' Forecasted FS>'!E58 -> 4.7147674 | F30: =' Forecasted FS>'!F9/' Forecasted FS>'!F58 -> 5.0219675 | G30: =' Forecasted FS>'!G9/' Forecasted FS>'!G58 -> 5.5633191 | H30: =' Forecasted FS>'!H9/' Forecasted FS>'!H58 -> 5.2643648 | I30: =' Forecasted FS>'!I9/' Forecasted FS>'!I58 -> 5.2901984 | K30: =IFERROR(AVERAGE(C30:I30),0) -> 4.8014907 | L30: =IFERROR(MEDIAN(C30:I30),0) -> 5.0219675
B31: Capital Turnover Ratio | C31: =' Forecasted FS>'!C9/' Forecasted FS>'!C52 -> 42.78558 | D31: =' Forecasted FS>'!D9/' Forecasted FS>'!D52 -> 47.303202 | E31: =' Forecasted FS>'!E9/' Forecasted FS>'!E52 -> 57.979504 | F31: =' Forecasted FS>'!F9/' Forecasted FS>'!F52 -> 70.936201 | G31: =' Forecasted FS>'!G9/' Forecasted FS>'!G52 -> 74.200869 | H31: =' Forecasted FS>'!H9/' Forecasted FS>'!H52 -> 78.625181 | I31: =' Forecasted FS>'!I9/' Forecasted FS>'!I52 -> 88.26581 | K31: =IFERROR(AVERAGE(C31:I31),0) -> 65.72805 | L31: =IFERROR(MEDIAN(C31:I31),0) -> 70.936201
B33: Debtor Days | C33: =365/C27 -> 74.321849 | D33: =365/D27 -> 70.092265 | E33: =365/E27 -> 68.108368 | F33: =365/F27 -> 63.227837 | G33: =365/G27 -> 71.715006 | H33: =365/H27 -> 69.775262 | I33: =365/I27 -> 71.986622 | K33: =IFERROR(AVERAGE(C33:I33),0) -> 69.889601 | L33: =IFERROR(MEDIAN(C33:I33),0) -> 70.092265
B34: Payable Days | C34: =365/C28 -> 87.307167 | D34: =365/D28 -> 93.854756 | E34: =365/E28 -> 107.73773 | F34: =365/F28 -> 101.69078 | G34: =365/G28 -> 93.92806 | H34: =365/H28 -> 97.973802 | I34: =365/I28 -> 106.77246 | K34: =IFERROR(AVERAGE(C34:I34),0) -> 98.466393 | L34: =IFERROR(MEDIAN(C34:I34),0) -> 97.973802
B35: Inventory Days | C35: =IFERROR(365/C29,0) -> 0 | D35: =IFERROR(365/D29,0) -> 0 | E35: =IFERROR(365/E29,0) -> 0 | F35: =IFERROR(365/F29,0) -> 0 | G35: =IFERROR(365/G29,0) -> 0 | H35: =IFERROR(365/H29,0) -> 0 | I35: =IFERROR(365/I29,0) -> 0 | K35: =IFERROR(AVERAGE(C35:I35),0) -> 0 | L35: =IFERROR(MEDIAN(C35:I35),0) -> 0
B36: Cash Conversion Cycle (in days) | C36: =C33+C35-C34 -> -12.985318 | D36: =D33+D35-D34 -> -23.762491 | E36: =E33+E35-E34 -> -39.62936 | F36: =F33+F35-F34 -> -38.462938 | G36: =G33+G35-G34 -> -22.213054 | H36: =H33+H35-H34 -> -28.19854 | I36: =I33+I35-I34 -> -34.785838 | K36: =IFERROR(AVERAGE(C36:I36),0) -> -28.576791 | L36: =IFERROR(MEDIAN(C36:I36),0) -> -28.19854
B38: CFO/Sales | C38: =' Forecasted FS>'!C82/' Forecasted FS>'!C9 -> 0.18727627 | D38: =' Forecasted FS>'!D82/' Forecasted FS>'!D9 -> 0.23114898 | E38: =' Forecasted FS>'!E82/' Forecasted FS>'!E9 -> 0.19635649 | F38: =' Forecasted FS>'!F82/' Forecasted FS>'!F9 -> 0.15307937 | G38: =' Forecasted FS>'!G82/' Forecasted FS>'!G9 -> 0.16405284 | H38: =' Forecasted FS>'!H82/' Forecasted FS>'!H9 -> 0.21899503 | I38: =' Forecasted FS>'!I82/' Forecasted FS>'!I9 -> 0.1902379 | K38: =IFERROR(AVERAGE(C38:I38),0) -> 0.19159241 | L38: =IFERROR(MEDIAN(C38:I38),0) -> 0.1902379
B39: CFO/Total Assets | C39: =' Forecasted FS>'!C9/' Forecasted FS>'!C69 -> 0.98900871 | D39: =' Forecasted FS>'!D9/' Forecasted FS>'!D69 -> 0.93452763 | E39: =' Forecasted FS>'!E9/' Forecasted FS>'!E69 -> 1.0420804 | F39: =' Forecasted FS>'!F9/' Forecasted FS>'!F69 -> 1.1779431 | G39: =' Forecasted FS>'!G9/' Forecasted FS>'!G69 -> 1.1297603 | H39: =' Forecasted FS>'!H9/' Forecasted FS>'!H69 -> 1.1028113 | I39: =' Forecasted FS>'!I9/' Forecasted FS>'!I69 -> 1.1578995 | K39: =IFERROR(AVERAGE(C39:I39),0) -> 1.0762901 | L39: =IFERROR(MEDIAN(C39:I39),0) -> 1.1028113
B40: CFO/Total Debt | C40: =' Forecasted FS>'!C9/(SUM(' Forecasted FS>'!C54:C55)) -> 3.4455787 | D40: =' Forecasted FS>'!D9/(SUM(' Forecasted FS>'!D54:D55)) -> 3.2243902 | E40: =' Forecasted FS>'!E9/(SUM(' Forecasted FS>'!E54:E55)) -> 2.9396795 | F40: =' Forecasted FS>'!F9/(SUM(' Forecasted FS>'!F54:F55)) -> 2.9837362 | G40: =' Forecasted FS>'!G9/(SUM(' Forecasted FS>'!G54:G55)) -> 3.2078741 | H40: =' Forecasted FS>'!H9/(SUM(' Forecasted FS>'!H54:H55)) -> 3.1358101 | I40: =' Forecasted FS>'!I9/(SUM(' Forecasted FS>'!I54:I55)) -> 2.9079042 | K40: =IFERROR(AVERAGE(C40:I40),0) -> 3.1207104 | L40: =IFERROR(MEDIAN(C40:I40),0) -> 3.1358101

Sheet Forecasted Key Drivers
B2: ='Raw Data Sheet'!B1& " - "& ' Forecasted FS>'!B9& " Forecasting" -> INFOSYS LTD - Sales Forecasting | G2: ='Raw Data Sheet'!B1 & "-" & ' Forecasted FS>'!B21& " Forecasting" -> INFOSYS LTD-EBITDA Forecasting | L2: ='Raw Data Sheet'!B1& "-" & ' Forecasted FS>'!B41& " Forecasting" -> INFOSYS LTD-EPS Forecasting
B3: Year Weight | C3: Year | D3: Sales | E3: Sales Growth | G3: Year Weight | H3: Year | I3: EBITDA | J3: EBITDA Growth | L3: Year Weight | M3: Year | N3: EPS | O3: EPS Growth
B4: 1 | C4: =' Forecasted FS>'!C5 -> 43921 | D4: {=TRANSPOSE('Raw Data Sheet'!E17:K17)} -> 90791 | G4: 1 | H4: =' Forecasted FS>'!C5 -> 43921 | I4: {=TRANSPOSE(' Forecasted FS>'!C21:J21)} -> 22267 | L4: 1 | M4: =' Forecasted FS>'!C5 -> 43921 | N4: {=TRANSPOSE(' Forecasted FS>'!C41:J41)} -> 32.486499
B5: =B4+1 -> 2 | C5: =C4+365 -> 44286 | D5: 100472 | E5: =D5/D4-1 -> 0.10662951 | G5: =G4+1 -> 2 | H5: =H4+365 -> 44286 | I5: 27889 | J5: =I5/I4-1 -> 0.25248125 | L5: =L4+1 -> 2 | M5: =M4+365 -> 44286 | N5: 40.420588 | O5: =N5/N4-1 -> 0.24422727
B6: =B5+1 -> 3 | C6: =C5+365 -> 44651 | D6: 121641 | E6: =D6/D5-1 -> 0.21069552 | G6: =G5+1 -> 3 | H6: =H5+365 -> 44651 | I6: 31491 | J6: =I6/I5-1 -> 0.12915486 | L6: =L5+1 -> 3 | M6: =M5+365 -> 44651 | N6: 47.189008 | O6: =N6/N5-1 -> 0.16744981
B7: =B6+1 -> 4 | C7: =C6+365 -> 45016 | D7: 146767 | E7: =D7/D6-1 -> 0.20655864 | G7: =G6+1 -> 4 | H7: =H6+365 -> 45016 | I7: 35130 | J7: =I7/I6-1 -> 0.11555683 | L7: =L6+1 -> 4 | M7: =M6+365 -> 45016 | N7: 51.60054 | O7: =N7/N6-1 -> 0.093486431
B8: =B7+1 -> 5 | C8: =C7+365 -> 45381 | D8: 153670 | E8: =D8/D7-1 -> 0.047033734 | G8: =G7+1 -> 5 | H8: =H7+365 -> 45381 | I8: 36425 | J8: =I8/I7-1 -> 0.03686308 | L8: =L7+1 -> 5 | M8: =M7+365 -> 45381 | N8: 51.885133 | O8: =N8/N7-1 -> 0.0055153183
B9: =B8+1 -> 6 | C9: =C8+365 -> 45746 | D9: 162990 | E9: =D9/D8-1 -> 0.060649444 | G9: =G8+1 -> 6 | H9: =H8+365 -> 45746 | I9: 39236 | J9: =I9/I8-1 -> 0.077172272 | L9: =L8+1 -> 6 | M9: =M8+365 -> 45746 | N9: 55.73881 | O9: =N9/N8-1 -> 0.074273236
B10: =B9+1 -> 7 | C10: =C9+365 -> 46111 | D10: 178650 | E10: =D10/D9-1 -> 0.096079514 | G10: =G9+1 -> 7 | H10: =H9+365 -> 46111 | I10: 42280 | J10: =I10/I9-1 -> 0.077581813 | L10: =L9+1 -> 7 | M10: =M9+365 -> 46111 | N10: 65.196272 | O10: =N10/N9-1 -> 0.16967463
B11: =B10+1 -> 8 | C11: =C10+365 -> 46476 | D11: =FORECAST(B11,$D$4:$D$10,$B$4:$B$10) -> 196517.57 | E11: =D11/D10-1 -> 0.10001439 | G11: =G10+1 -> 8 | H11: =H10+365 -> 46476 | I11: =FORECAST(G11,$I$4:$I$10,$G$4:$G$10) -> 46055 | J11: =I11/I10-1 -> 0.089285714 | L11: =L10+1 -> 8 | M11: =M10+365 -> 46476 | N11: =FORECAST(L11,$N$4:$N$10,$L$4:$L$10) -> 68.282677 | O11: =N11/N10-1 -> 0.047340207
B12: =B11+1 -> 9 | C12: =C11+365 -> 46841 | D12: =FORECAST(B12,$D$4:$D$10,$B$4:$B$10) -> 211540.5 | E12: =D12/D11-1 -> 0.076445727 | G12: =G11+1 -> 9 | H12: =H11+365 -> 46841 | I12: =FORECAST(G12,$I$4:$I$10,$G$4:$G$10) -> 49185.964 | J12: =I12/I11-1 -> 0.067983157 | L12: =L11+1 -> 9 | M12: =M11+365 -> 46841 | N12: =FORECAST(L12,$N$4:$N$10,$L$4:$L$10) -> 73.049173 | O12: =N12/N11-1 -> 0.069805347
B13: =B12+1 -> 10 | C13: =C12+365 -> 47206 | D13: =FORECAST(B13,$D$4:$D$10,$B$4:$B$10) -> 226563.43 | E13: =D13/D12-1 -> 0.071016796 | G13: =G12+1 -> 10 | H13: =H12+365 -> 47206 | I13: =FORECAST(G13,$I$4:$I$10,$G$4:$G$10) -> 52316.929 | J13: =I13/I12-1 -> 0.063655645 | L13: =L12+1 -> 10 | M13: =M12+365 -> 47206 | N13: =FORECAST(L13,$N$4:$N$10,$L$4:$L$10) -> 77.815669 | O13: =N13/N12-1 -> 0.065250513
B14: =B13+1 -> 11 | C14: =C13+365 -> 47571 | D14: =FORECAST(B14,$D$4:$D$10,$B$4:$B$10) -> 241586.36 | E14: =D14/D13-1 -> 0.066307827 | G14: =G13+1 -> 11 | H14: =H13+365 -> 47571 | I14: =FORECAST(G14,$I$4:$I$10,$G$4:$G$10) -> 55447.893 | J14: =I14/I13-1 -> 0.059846103 | L14: =L13+1 -> 11 | M14: =M13+365 -> 47571 | N14: =FORECAST(L14,$N$4:$N$10,$L$4:$L$10) -> 82.582165 | O14: =N14/N13-1 -> 0.061253679
B15: =B14+1 -> 12 | C15: =C14+365 -> 47936 | D15: =FORECAST(B15,$D$4:$D$10,$B$4:$B$10) -> 256609.29 | E15: =D15/D14-1 -> 0.062184507 | G15: =G14+1 -> 12 | H15: =H14+365 -> 47936 | I15: =FORECAST(G15,$I$4:$I$10,$G$4:$G$10) -> 58578.857 | J15: =I15/I14-1 -> 0.056466786 | L15: =L14+1 -> 12 | M15: =M14+365 -> 47936 | N15: =FORECAST(L15,$N$4:$N$10,$L$4:$L$10) -> 87.348661 | O15: =N15/N14-1 -> 0.057718225

Sheet Raw Data Sheet
A1: COMPANY NAME | B1: INFOSYS LTD
A2: LATEST VERSION | B2: 2.1 | E2: PLEASE DO NOT MAKE ANY CHANGES TO THIS SHEET
A3: CURRENT VERSION | B3: 2.1
A5: META
A6: Number of shares | B6: =IF(B9>0, B9/B8, 0) -> 404.06048
A7: Face Value | B7: 5
A8: Current Price | B8: 1040.9
A9: Market Capitalization | B9: 420586.55
A15: PROFIT & LOSS
A16: Report Date | B16: 42825 | C16: 43190 | D16: 43555 | E16: 43921 | F16: 44286 | G16: 44651 | H16: 45016 | I16: 45382 | J16: 45747 | K16: 46112
A17: Sales | B17: 68484 | C17: 70522 | D17: 82675 | E17: 90791 | F17: 100472 | G17: 121641 | H17: 146767 | I17: 153670 | J17: 162990 | K17: 178650
A18: Raw Material Cost
A19: Change in Inventory
A20: Power and Fuel | B20: 228 | C20: 207 | D20: 221 | E20: 229 | F20: 143 | G20: 132 | H20: 176 | I20: 199 | J20: 222 | K20: 223
A21: Other Mfr. Exp | B21: 6712 | C21: 7286 | D21: 9902 | E21: 11086 | F21: 12800 | G21: 20690 | H21: 26330 | I21: 27195 | J21: 30395 | K21: 32922
A22: Employee Cost | B22: 37669 | C22: 38902 | D22: 45323 | E22: 50895 | F22: 55547 | G22: 63997 | H22: 78374 | I22: 82636 | J22: 85968 | K22: 95112
A23: Selling and admin | B23: 4584 | C23: 4585 | D23: 5553 | E23: 5375 | F23: 3194 | G23: 4305 | H23: 5300 | I23: 5705 | J23: 6039 | K23: 6784
A24: Other Expenses | B24: 687 | C24: 720 | D24: 1506 | E24: 939 | F24: 899 | G24: 1026 | H24: 1457 | I24: 1510 | J24: 1130 | K24: 1329
A25: Other Income | B25: 3050 | C25: 3311 | D25: 2882 | E25: 2803 | F25: 2201 | G25: 2295 | H25: 2701 | I25: 4711 | J25: 3600 | K25: 3033
A26: Depreciation | B26: 1703 | C26: 1863 | D26: 2011 | E26: 2893 | F26: 3267 | G26: 3476 | H26: 4225 | I26: 4678 | J26: 4812 | K26: 4902
A27: Interest | E27: 170 | F27: 195 | G27: 200 | H27: 284 | I27: 470 | J27: 416 | K27: 416
A28: Profit before tax | B28: 19951 | C28: 20270 | D28: 21041 | E28: 22007 | F28: 26628 | G28: 30110 | H28: 33322 | I28: 35988 | J28: 37608 | K28: 39995
A29: Tax | B29: 5598 | C29: 4241 | D29: 5631 | E29: 5368 | F29: 7205 | G29: 7964 | H29: 9214 | I29: 9740 | J29: 10858 | K29: 10521
A30: Net profit | B30: 14353 | C30: 16029 | D30: 15404 | E30: 16594 | F30: 19351 | G30: 22110 | H30: 24095 | I30: 26233 | J30: 26713 | K30: 29440
A31: Dividend Amount | B31: 5891.6 | C31: 9465.6 | D31: 9222.5 | E31: 7427 | F31: 11469.6 | G31: 13007.6 | H31: 14069.2 | I31: 19053.2 | J31: 17827.8 | K31: 19430.4
A40: Quarters
A41: Report Date | B41: 45382 | C41: 45473 | D41: 45565 | E41: 45657 | F41: 45747 | G41: 45838 | H41: 45930 | I41: 46022 | J41: 46112 | K41: 46203
A42: Sales | B42: 37923 | C42: 39315 | D42: 40986 | E42: 41764 | F42: 40925 | G42: 42279 | H42: 44490 | I42: 45479 | J42: 46402 | K42: 48211
A43: Expenses | B43: 29139 | C43: 29878 | D43: 31177 | E43: 31649 | F43: 31051 | G43: 32336 | H43: 33955 | I43: 34845 | J43: 35235 | K43: 36802
A44: Other Income | B44: 2729 | C44: 838 | D44: 712 | E44: 859 | F44: 1190 | G44: 1042 | H44: 982 | I44: -150 | J44: 1159 | K44: 984
A45: Depreciation | B45: 1163 | C45: 1149 | D45: 1160 | E45: 1203 | F45: 1299 | G45: 1140 | H45: 1182 | I45: 1155 | J45: 1424 | K45: 1246
A46: Interest | B46: 110 | C46: 105 | D46: 108 | E46: 101 | F46: 102 | G46: 105 | H46: 106 | I46: 100 | J46: 105 | K46: 119
A47: Profit before tax | B47: 10240 | C47: 9021 | D47: 9253 | E47: 9670 | F47: 9663 | G47: 9740 | H47: 10229 | I47: 9229 | J47: 10797 | K47: 11028
A48: Tax | B48: 2265 | C48: 2647 | D48: 2737 | E48: 2848 | F48: 2625 | G48: 2816 | H48: 2854 | I48: 2563 | J48: 2288 | K48: 3253
A49: Net profit | B49: 7969 | C49: 6368 | D49: 6506 | E49: 6806 | F49: 7033 | G49: 6921 | H49: 7364 | I49: 6654 | J49: 8501 | K49: 7769
A50: Operating Profit | B50: 8784 | C50: 9437 | D50: 9809 | E50: 10115 | F50: 9874 | G50: 9943 | H50: 10535 | I50: 10634 | J50: 11167 | K50: 11409
A55: BALANCE SHEET
A56: Report Date | B56: 42825 | C56: 43190 | D56: 43555 | E56: 43921 | F56: 44286 | G56: 44651 | H56: 45016 | I56: 45382 | J56: 45747 | K56: 46112
A57: Equity Share Capital | B57: 1144 | C57: 1088 | D57: 2170 | E57: 2122 | F57: 2124 | G57: 2098 | H57: 2069 | I57: 2071 | J57: 2073 | K57: 2024
A58: Reserves | B58: 67838 | C58: 63835 | D58: 62778 | E58: 63328 | F58: 74227 | G58: 73252 | H58: 73338 | I58: 86045 | J58: 93745 | K58: 90828
...

Sheet Raw Cash Flow 
B2: Particulars | C2: 42064 | D2: 42430 | E2: 42795 | F2: 43160 | G2: 43525 | H2: 43891 | I2: 44256 | J2: 44621 | K2: 44986 | L2: 45352 | M2: 45717 | N2: 46082
A3: # | B3: Cash from Operating Activity - | C3: 8353 | D3: 10028 | E3: 11531 | F3: 13218 | G3: 14841 | H3: 17003 | I3: 23224 | J3: 23885 | K3: 22467 | L3: 25210 | M3: 35694 | N3: 33986
B4: Profit from operations | C4: 15946 | D4: 17839 | E4: 19340 | F4: 19963 | G4: 22126 | H4: 23920 | I4: 28845 | J4: 32921 | K4: 37605 | L4: 39523 | M4: 41591 | N4: 45273
B5: Receivables | C5: -1475 | D5: -1654 | E5: -1743 | F5: -1523 | G5: -2881 | H5: -3861 | I5: -1835 | J5: -7937 | K5: -7076 | L5: -2667 | M5: -1769 | N5: -5177
B6: Payables | C6: 0 | D6: 242 | E6: -19 | F6: 328 | G6: 916 | H6: -373 | I6: -245 | J6: 1489 | K6: -279 | L6: 91 | M6: 176 | N6: -26
B7: Loans Advances | C7: -221 | D7: -1134 | E7: 0 | F7: 0 | G7: 0 | H7: 0 | I7: -534 | J7: -1914 | K7: -3108 | L7: -1172 | M7: -1024 | N7: -2645
B8: Other WC items | C8: 854 | D8: 600 | E8: -394 | F8: 1279 | G8: 1512 | H8: 1867 | I8: 3382 | J8: 6938 | K8: 4119 | L8: -1334 | M8: 2322 | N8: 5209
B9: Working capital changes | C9: -842 | D9: -1946 | E9: -2156 | F9: 84 | G9: -453 | H9: -2367 | I9: 768 | J9: -1424 | K9: -6344 | L9: -5082 | M9: -295 | N9: -2639
B10: Direct taxes | C10: -6751 | D10: -5865 | E10: -5653 | F10: -6829 | G10: -6832 | H10: -4550 | I10: -6389 | J10: -7612 | K10: -8794 | L10: -9231 | M10: -5602 | N10: -8648
A11: # | B11: Cash from Investing Activity - | C11: 999 | D11: -885 | E11: -14664 | F11: 4533 | G11: -632 | H11: -331 | I11: -7373 | J11: -6485 | K11: -1071 | L11: -5093 | M11: -1864 | N11: 3546
B12: Fixed assets purchased | C12: -2247 | D12: -2723 | E12: -2760 | F12: -1998 | G12: -2445 | H12: -3307 | I12: -2107 | J12: -2161 | K12: -2579 | L12: -2201 | M12: -2237 | N12: -2727
B13: Investments purchased | C13: -23923 | D13: -24577 | E13: -66410 | F13: -69159 | G13: -79410 | H13: -37482 | I13: -46738 | J13: -59951 | K13: -75800 | L13: -78092 | M13: -82742 | N13: -82617
B14: Investments sold | C14: 25253 | D14: 24980 | E14: 52048 | F14: 74003 | G14: 78098 | H14: 38861 | I14: 40381 | J14: 57356 | K14: 76722 | L14: 72930 | M14: 84877 | N14: 89699
B15: Interest received | C15: 2551 | D15: 2383 | E15: 0 | F15: 0 | G15: 0 | H15: 0 | I15: 0 | J15: 0 | K15: 0 | L15: 0 | M15: 0 | N15: 0
B16: Dividends received | C16: 0 | D16: 0 | E16: 2753 | F16: 1768 | G16: 1557 | H16: 1929 | I16: 1418 | J16: 1898 | K16: 1525 | L16: 1768 | M16: 2040 | N16: 2713
B17: Acquisition of companies | C17: -1376 | D17: -747 | E17: 0 | F17: 0 | G17: 0 | H17: 0 | I17: 0 | J17: 0 | K17: 0 | L17: 0 | M17: 0 | N17: 0
B18: Inter corporate deposits | C18: 0 | D18: -142 | E18: -164 | F18: -130 | G18: -24 | H18: -108 | I18: 0 | J18: 0 | K18: 0 | L18: 0 | M18: 0 | N18: 0
B19: Other investing items | C19: 741 | D19: -59 | E19: -131 | F19: 49 | G19: 1592 | H19: -224 | I19: -327 | J19: -3627 | K19: -939 | L19: 502 | M19: -3802 | N19: -3522
A20: # | B20: Cash from Financing Activity - | C20: -4935 | D20: -6813 | E20: -6939 | F20: -20505 | G20: -14512 | H20: -17591 | I20: -9786 | J20: -24642 | K20: -26695 | L20: -17504 | M20: -24161 | N20: -39786
B21: Proceeds from shares | C21: 0 | D21: 0 | E21: 0 | F21: 5 | G21: 6 | H21: 6 | I21: 15 | J21: 21 | K21: 35 | L21: 5 | M21: 6 | N21: 2
B22: Repayment of borrowings | C22: 0 | D22: 0 | E22: 0 | F22: 0 | G22: 0 | H22: 0 | I22: 0 | J22: 0 | K22: 0 | L22: 0 | M22: -985 | N22: 0
B23: Dividends paid | C23: -4935 | D23: -6813 | E23: -6939 | F23: -7464 | G23: -13705 | H23: -9548 | I23: -9137 | J23: -12731 | K23: -13653 | L23: -14731 | M23: -20289 | N23: -18656
B24: Financial liabilities | C24: 0 | D24: 0 | E24: 0 | F24: 0 | G24: 0 | H24: -571 | I24: -698 | J24: -915 | K24: -1231 | L24: -2024 | M24: -2355 | N24: -2824
B25: Other financing items | C25: 0 | D25: 0 | E25: 0 | F25: -13046 | G25: -813 | H25: -7478 | I25: 34 | J25: -11017 | K25: -11846 | L25: -754 | M25: -538 | N25: -18308
A26: # | B26: Net Cash Flow | C26: 4417 | D26: 2330 | E26: -10072 | F26: -2754 | G26: -303 | H26: -919 | I26: 6065 | J26: -7242 | K26: -5299 | L26: 2613 | M26: 9669 | N26: -2254
B27: Free Cash Flow | C27: 6106 | D27: 7305 | E27: 8771 | F27: 11220 | G27: 12396 | H27: 13696 | I27: 21117 | J27: 21724 | K27: 19888 | L27: 23009 | M27: 33457 | N27: 31259

Sheet WACC>
B2: Calculation Of WACC
B5: Weighted Average Cost of Capital
B7: All Figures are in INR(Crores) unless stated otherwise
B9: Peer Comps
H10: Debt/ | I10: Debt/ | J10: Levered | K10: Unlevered
B11: Name of the Comp | D11: Country | E11: Total Debt | F11: Total Equity | G11: Tax Rate 1 | H11: Equity | I11: Capital | J11: Beta 2 | K11: Beta 3
B13: ='Data - Comps'!C3 -> Infosys | D13: India | E13: ='Data - Comps'!F3 -> 8737 | F13: ='Data - Comps'!E3 -> 468958.99 | G13: 0.3 | H13: =E13/F13 -> 0.018630627 | I13: =E13/(E13+F13) -> 0.018289875 | J13: ='Infosys - Beta'!J8 -> 0.67533945 | K13: =J13/(1+(1-G13)*H13) -> 0.66664543
B14: ='Data - Comps'!C4 -> TCS | D14: India | E14: ='Data - Comps'!F4 -> 11283 | F14: ='Data - Comps'!E4 -> 885374.85 | G14: 0.3 | H14: =E14/F14 -> 0.012743755 | I14: =E14/(E14+F14) -> 0.012583395 | J14: ='TCS - Beta'!J8 -> -0.077447364 | K14: =J14/(1+(1-G14)*H14) -> -0.076762594
B15: ='Data - Comps'!C5 -> HCL Technologies | D15: India | E15: ='Data - Comps'!F5 -> 5215 | F15: ='Data - Comps'!E5 -> 364812.07 | G15: 0.3 | H15: =E15/F15 -> 0.014295031 | I15: =E15/(E15+F15) -> 0.014093563 | J15: ='HCL Technologies - Beta'!J8 -> 0.7844093 | K15: =J15/(1+(1-G15)*H15) -> 0.77663786
B16: ='Data - Comps'!C6 -> Wipro | D16: India | E16: ='Data - Comps'!F6 -> 20291 | F16: ='Data - Comps'!E6 -> 181880.46 | G16: 0.3 | H16: =E16/F16 -> 0.11156229 | I16: =E16/(E16+F16) -> 0.1003653 | J16: ='WIPRO - Beta'!J8 -> 1.4755079 | K16: =J16/(1+(1-G16)*H16) -> 1.3686269
B17: ='Data - Comps'!C7 -> Tech Mahindra | D17: India | E17: ='Data - Comps'!F7 -> 2186.2 | F17: ='Data - Comps'!E7 -> 161201.84 | G17: 0.3 | H17: =E17/F17 -> 0.01356188 | I17: =E17/(E17+F17) -> 0.013380416 | J17: ='Tech Mahindra - Beta'!J8 -> 0.6902984 | K17: =J17/(1+(1-G17)*H17) -> 0.68380681
F19: Average | G19: =AVERAGE(G13:G17) -> 0.3 | H19: =AVERAGE(H13:H17) -> 0.034158716 | I19: =AVERAGE(I13:I17) -> 0.031742511 | J19: =AVERAGE(J13:J17) -> 0.70962154 | K19: =AVERAGE(K13:K17) -> 0.68379088
F20: Median | G20: =MEDIAN(G13:G17) -> 0.3 | H20: =MEDIAN(H13:H17) -> 0.014295031 | I20: =MEDIAN(I13:I17) -> 0.014093563 | J20: =MEDIAN(J13:J17) -> 0.6902984 | K20: =MEDIAN(K13:K17) -> 0.68380681
B23: Cost of Debt | G23: Cost of Equity
B25: Pre-Tax Cost of Debt | E25: 0.1037 | G25: Risk Free Rate | K25: 0.0658
B26: Tax rate | E26: =G20 -> 0.3 | G26: Equity Risk Premium | K26: =Rm!G9-'WACC>'!K25 -> 0.098692308
B27: Post-Tax Cost of Debt | E27: =E25*(1-E26) -> 0.07259 | G27: Levered Beta 4 | K27: =K36 -> 0.69949894
G28: Cost of Equity | K28: =K25+K27*K26 -> 0.13483516
B31: Capital Structure | G31: Levered Beta
D33: Current | E33: Target | G33: Comps Median Unlevered Data | K33: =K20 -> 0.68380681
B34: Total Debt | C34: =E13 -> 8737 | D34: =C34/$C$36 -> 0.018289875 | E34: =I19 -> 0.031742511 | G34: Target Debt/Equity | K34: =E38 -> 0.03278313
B35: Market Capitalization | C35: =F13 -> 468958.99 | D35: =C35/$C$36 -> 0.98171012 | E35: =E36-E34 -> 0.96825749 | G35: Tax Rate | K35: =E26 -> 0.3
B36: Total Capital | C36: =SUM(C34:C35) -> 477695.99 | D36: =C36/$C$36 -> 1 | E36: =D36 -> 1 | G36: Levered Beta | K36: =K33*(1+(1-K35)*K34) -> 0.69949894
B38: Debt/Equity | D38: =D34/D35 -> 0.018630627 | E38: =E34/E35 -> 0.03278313 | G38: Weighted Average Cost of Capital
B40: Notes: | J40: Total Cost | K40: Total Weight
B41: 1. Tax Rate considered as marginal rate of country | G41: Debt | J41: =E27 -> 0.07259 | K41: =E34 -> 0.031742511
B42: 2. Levered Beta is based on monthly data | G42: Equity | J42: =K28 -> 0.13483516 | K42: =E35 -> 0.96825749
B43: 3. Unlevered Beta = Levered Beta/(1+(1-Tax rate)*Debt/Equity) | G43: Weighted Average Cost of Capital | K43: =SUMPRODUCT(J41:J42,K41:K42) -> 0.13285935
B44: 4. Levered Beta = UnLevered Beta*(1+(1-Tax rate)*Debt/Equity)

Sheet Data - Comps
B2: S.No. | C2: Name | D2: CMP Rs. | E2: Mar Cap Rs.Cr. | F2: Debt Rs.Cr. | G2: Debt / Eq
B3: 1 | C3: Infosys | D3: 1155.6 | E3: 468958.99 | F3: 8737 | G3: 0.1
B4: 2 | C4: TCS | D4: 2446.6 | E4: 885374.85 | F4: 11283 | G4: 0.11
B5: 3 | C5: HCL Technologies | D5: 1344.3 | E5: 364812.07 | F5: 5215 | G5: 0.07
B6: 4 | C6: Wipro | D6: 183.61 | E6: 181880.46 | F6: 20291 | G6: 0.23
B7: 5 | C7: Tech Mahindra | D7: 1644.2 | E7: 161201.84 | F7: 2186.2 | G7: 0.07
B9: Source: Screener.in

Sheet Infosys - Beta
B2: Source: Investing.com
B4: Regression Beta - 2 Years Weekly
B6: Infosys Weekly Returns | F6: NIFTY Returns | I6: Beta Drifting
B8: Date | C8: Closing Price | D8: Return | F8: Closing Price | G8: Return | I8: Levered Raw Beta | J8: =SLOPE(D10:D112,G10:G112) -> 0.67533945
B9: 07/28/2024 | C9: 1821.2 | F9: 24717.7 | I9: Raw Beta Weight | J9: 0.75
B10: 45390 | C10: 1770.75 | D10: =C10/C9-1 -> -0.027701515 | F10: 24367.5 | G10: =F10/F9-1 -> -0.014167985
B11: 45604 | C11: 1858.95 | D11: =C11/C10-1 -> 0.049809403 | F11: 24541.15 | G11: =F11/F10-1 -> 0.0071262953 | I11: Market Beta | J11: 1
B12: 08/18/2024 | C12: 1862.1 | D12: =C12/C11-1 -> 0.001694505 | F12: 24823.15 | G12: =F12/F11-1 -> 0.011490904 | I12: Market Beta Weight | J12: =100%-J9 -> 0.25
B13: 08/25/2024 | C13: 1943.7 | D13: =C13/C12-1 -> 0.043821492 | F13: 25235.9 | G13: =F13/F12-1 -> 0.016627624
B14: 45300 | C14: 1901.85 | D14: =C14/C13-1 -> -0.0215311 | F14: 24852.15 | G14: =F14/F13-1 -> -0.015206511 | I14: Adjusted Beta | J14: =(J8*J9)+(J11*J12) -> 0.75650459
B15: 45513 | C15: 1944.1 | D15: =C15/C14-1 -> 0.022215212 | F15: 25356.5 | G15: =F15/F14-1 -> 0.020294019
B16: 09/15/2024 | C16: 1905.75 | D16: =C16/C15-1 -> -0.019726352 | F16: 25790.95 | G16: =F16/F15-1 -> 0.017133674
B17: 09/22/2024 | C17: 1906.75 | D17: =C17/C16-1 -> 0.0005247278 | F17: 26178.95 | G17: =F17/F16-1 -> 0.015044037
B18: 09/29/2024 | C18: 1918.15 | D18: =C18/C17-1 -> 0.0059787597 | F18: 25014.6 | G18: =F18/F17-1 -> -0.044476574
B19: 45453 | C19: 1935.1 | D19: =C19/C18-1 -> 0.0088366395 | F19: 24964.25 | G19: =F19/F18-1 -> -0.0020128245
B20: 10/13/2024 | C20: 1879.6 | D20: =C20/C19-1 -> -0.028680688 | F20: 24854.05 | G20: =F20/F19-1 -> -0.0044143125
B21: 10/20/2024 | C21: 1862.05 | D21: =C21/C20-1 -> -0.009337093 | F21: 24180.8 | G21: =F21/F20-1 -> -0.027088141
B22: 10/27/2024 | C22: 1760.85 | D22: =C22/C21-1 -> -0.054348702 | F22: 24304.35 | G22: =F22/F21-1 -> 0.0051094257
B23: 45362 | C23: 1829.95 | D23: =C23/C22-1 -> 0.039242411 | F23: 24148.2 | G23: =F23/F22-1 -> -0.0064247758
B24: 45576 | C24: 1864.55 | D24: =C24/C23-1 -> 0.01890762 | F24: 23532.7 | G24: =F24/F23-1 -> -0.025488442
B25: 11/17/2024 | C25: 1902.25 | D25: =C25/C24-1 -> 0.020219356 | F25: 23907.25 | G25: =F25/F24-1 -> 0.015916151
B26: 11/24/2024 | C26: 1857.85 | D26: =C26/C25-1 -> -0.023340781 | F26: 24131.1 | G26: =F26/F25-1 -> 0.0093632685
B27: 45303 | C27: 1922.4 | D27: =C27/C26-1 -> 0.034744463 | F27: 24677.8 | G27: =F27/F26-1 -> 0.022655411
B28: 45516 | C28: 1999.7 | D28: =C28/C27-1 -> 0.040210154 | F28: 24768.3 | G28: =F28/F27-1 -> 0.0036672637
B29: 12/15/2024 | C29: 1922.15 | D29: =C29/C28-1 -> -0.038780817 | F29: 23587.5 | G29: =F29/F28-1 -> -0.047673841
B30: 12/22/2024 | C30: 1916.75 | D30: =C30/C29-1 -> -0.0028093541 | F30: 23813.4 | G30: =F30/F29-1 -> 0.0095771065
B31: 12/29/2024 | C31: 1938.75 | D31: =C31/C30-1 -> 0.011477762 | F31: 24004.75 | G31: =F31/F30-1 -> 0.0080353918
B32: 45778 | C32: 1966.95 | D32: =C32/C31-1 -> 0.014545455 | F32: 23431.5 | G32: =F32/F31-1 -> -0.02388069
B33: 45992 | C33: 1815.45 | D33: =C33/C32-1 -> -0.077022802 | F33: 23203.2 | G33: =F33/F32-1 -> -0.0097432943
B34: 01/19/2025 | C34: 1875.45 | D34: =C34/C33-1 -> 0.033049657 | F34: 23092.2 | G34: =F34/F33-1 -> -0.0047838229
B35: 01/26/2025 | C35: 1879.8 | D35: =C35/C34-1 -> 0.0023194433 | F35: 23508.4 | G35: =F35/F34-1 -> 0.018023402
B36: 45690 | C36: 1903.65 | D36: =C36/C35-1 -> 0.01268752 | F36: 23559.95 | G36: =F36/F35-1 -> 0.0021928332
B37: 45902 | C37: 1856.4 | D37: =C37/C36-1 -> -0.024820739 | F37: 22929.25 | G37: =F37/F36-1 -> -0.026770006
B38: 02/16/2025 | C38: 1815 | D38: =C38/C37-1 -> -0.022301228 | F38: 22795.9 | G38: =F38/F37-1 -> -0.0058157157
B39: 02/23/2025 | C39: 1687.7 | D39: =C39/C38-1 -> -0.070137741 | F39: 22124.7 | G39: =F39/F38-1 -> -0.029443891
B40: 45691 | C40: 1686 | D40: =C40/C39-1 -> -0.001007288 | F40: 22552.5 | G40: =F40/F39-1 -> 0.019335855
B41: 45903 | C41: 1579.85 | D41: =C41/C40-1 -> -0.062959668 | F41: 22397.2 | G41: =F41/F40-1 -> -0.0068861545
B42: 03/16/2025 | C42: 1592.55 | D42: =C42/C41-1 -> 0.0080387379 | F42: 23350.4 | G42: =F42/F41-1 -> 0.042558891
B43: 03/23/2025 | C43: 1570.65 | D43: =C43/C42-1 -> -0.013751531 | F43: 23519.35 | G43: =F43/F42-1 -> 0.0072354221
B44: 03/30/2025 | C44: 1451.65 | D44: =C44/C43-1 -> -0.075764811 | F44: 22904.45 | G44: =F44/F43-1 -> -0.02614443
...

Sheet TCS - Beta
B2: Source: Investing.com
B4: Regression Beta - 2 Years Weekly
B6: TCS Weekly Returns | F6: NIFTY Returns | I6: Beta Drifting
L7: Beta 2 | M7: =_xlfn.COVARIANCE.S(D10:D113,G10:G113)/_xlfn.VAR.S(G10:G113) -> -0.077447364
B8: Date | C8: Closing Price | D8: Return | F8: Closing Price | G8: Return | I8: Levered Raw Beta | J8: =SLOPE(D10:D113,G10:G113) -> -0.077447364
B9: 07/28/2024 | C9: 4215.85 | F9: 14529.2 | I9: Raw Beta Weight | J9: 0.75 | L9: Beta | M9: =M28 -> 1.2421252
B10: 45390 | C10: 4162.4 | D10: =C10/C9-1 -> -0.012678345 | F10: 14938.1 | G10: =F10/F9-1 -> 0.028143325
